Workbook

Sheet Formulario
B1: FORMULARIO - EVALUACIÓN EX POST
B2: ACLARACIÓN METODOLÓGICA:
B3: Los datos a ingresar corresponden únicamente a aquellas celdas identificadas con color amarillo y/o que contengan texto en azul. Los valores y fechas que allí figuran son arbitrarios, al sólo efecto de que las celdas dependientes no den señal de error.
B4: Las celdas con texto en rojo se calculan automáticamente (contienen fórmulas).
B7: BAPIN Nro. | D7: 999999 - Puesta en valor del Aeropuerto XX - Operación de cargas
B9: Información registrada en el BAPIN al xx/xx/xx hh:mm
B11: 2.1. Datos Generales
B13: Jurisdicción | F13: 57 | H13: Ministerio de Transporte
B15: SAF | F15: 664 | H15: Organismo Rector del Sistema Nacional de Aeropuertos (ORSNA)
B17: Programa | F17: 16 | H17: Control del Sistema de Aeropuertos
B19: Subprograma
B21: 2.2. Denominación del Proyecto de Inversión
B23: 999999 | D23: Puesta en valor del Aeropuerto X - Operación de cargas
B25: 2.3. Contribución
B27: 2.4. Modalidad de Contratación
B29: 2.5. Finalidad Función Subfunción
B31: 2.6. Localización Geográfica
B33: 2.7. Origen del Financiamiento Externo
B35: Préstamo | D35: Denominación
B38: 2.8. Proyectos Relacionados
B40: Tipo | D40: Código BAPIN | F40: Denominación
B46: 2.9. Principios Conceptuales de Formulación
B48: 1. ¿Cuál es la necesidad a satisfacer o la problemática a solucionar con el presente proyecto de inversión?
B50: El aeropuerto de XX recibe solo vuelos ocasionales, debido a que en su condición actual no cumple con las regulaciones ni tiene las condiciones mínimas para que operen aviones de mayor porte. En consecuencia, está perdiendo la oportunidad de transformarse en un hub de salida de la producción de las economías regionales cercanas. Esa producción recorre hoy z kilómetros para exportarse por el aeropuerto internacional más cercano.
B52: 2. ¿Cuál es el objetivo del proyecto?
B54: Que el aeropuerto XX alcance los estándares de seguridad y operación necesarios como para operar con vuelos de cargan nacional e internacional.
B56: 3. ¿Cuál es el producto o servicio que brindará el proyecto una vez finalizado?
B58: Operación de aviones de carga, para vuelos nacionales e internacionales.
B60: 4. ¿Qué alternativas han sido consideradas para satisfacer la necesidad o resolver la problemática planteada?
B62: Se evaluó establecer un circuito de bi-trenes hasta el aeropuerto internacional más cercano.
B64: 4B. Ordene las respuestas anteriores en una secuencia Efecto - Problema - Causa, y ubique al proyecto
B66: Secuencia Lógica | H66: Secuencia para el Proyecto | L66: ¿Dónde se ubica el proyecto?
B67: Efecto Problemático Observado | H67: Altos costos de salida de la producción exportable regional
B68: Situación Problemática causante del Efecto | H68: Aeropuerto no apto para aviones de carga "grandes"
B69: Causa Principal de la Situación Problemática | H69: Deficiencias en la infraestructura de pista y de ilumnicación del aeropuerto | L69: Puesta en valor del aeropuerto por repavimentación de pista e instalación de ILS
B71: 5. ¿Por qué han seleccionado al proyecto como la alternativa elegida?
B73: La comparación con la mejora alternativa (sistema de bi-trenes) muestra que el proyecto presenta mejores indicadores de rentabilidad.
B76: 5B. ¿Cuál es la mejor alternativa que se dejó de lado por el proyecto?
B78: Aprovechar la autopista entre A y B para agregar un doble carril (de dos sentidos de circulación) e implementar un sistema de bi-trenes.
B80: 6. ¿Cuál será la capacidad prestacional del proyecto una vez finalizado?
...

Sheet Formulario redet
A1: EVALUACIÓN DE TERMINACIÓN | N1: ACLARACIÓN:
A2: FORMULARIOS | N2: Los datos que deben cargarse son únicamente los
A3: El Paramillo, Mendoza, Colector Boedo – Ponce | N3: que están en celdas con letras azules.
B5: BAPIN Nro. | D5: 999999 - Puesta en valor del Aeropuerto XX - Operación de cargas
B7: Información registrada en el BAPIN al xx/xx/xx hh:mm
B9: 2.1. Datos Generales
B11: Jurisdicción | F11: 57 | H11: Ministerio de Transporte
B13: SAF | F13: 664 | H13: Organismo Rector del Sistema Nacional de Aeropuertos (ORSNA)
B15: Programa | F15: 16 | H15: Control del Sistema de Aeropuertos
B17: Subprograma
B19: 2.2. Denominación del Proyecto de Inversión
B21: 999999 | D21: Puesta en valor del Aeropuerto X - Operación de cargas
B23: 2.3. Contribución
B25: 2.4. Modalidad de Contratación
B27: 2.5. Finalidad Función Subfunción
B29: 2.6. Localización Geográfica
B31: 2.7. Origen del Financiamiento Externo
B33: Préstamo | D33: Denominación
B36: 2.8. Proyectos Relacionados
B38: Tipo | D38: Código BAPIN | F38: Denominación
B44: 2.9. Principios Conceptuales de Formulación
B46: 1. ¿Cuál es la necesidad a satisfacer o la problemática a solucionar con el presente proyecto de inversión?
B48: El aeropuerto de XX recibe solo vuelos ocasionales, debido a que en su condición actual no cumple con las regulaciones ni tiene las condiciones mínimas para que operen aviones de mayor porte. En consecuencia, está perdiendo la oportunidad de transformarse en un hub de salida de la producción de las economías regionales cercanas. Esa producción recorre hoy z kilómetros para exportarse por el aeropuerto internacional más cercano.
B50: 2. ¿Cuál es el objetivo del proyecto?
B52: Que el aeropuerto XX alcance los estándares de seguridad y operación necesarios como para operar con vuelos de cargan nacional e internacional.
B54: 3. ¿Cuál es el producto o servicio que brindará el proyecto una vez finalizado?
B56: Operación de aviones de carga, para vuelos nacionales e internacionales.
B58: 4. ¿Qué alternativas han sido consideradas para satisfacer la necesidad o resolver la problemática planteada?
B60: Se evaluó establecer un circuito de bi-trenes hasta el aeropuerto internacional más cercano.
B62: 4B. Ordene las respuestas anteriores en una secuencia Efecto - Problema - Causa, y ubique al proyecto
B64: Secuencia Lógica | H64: Secuencia para el Proyecto | L64: ¿Dónde se ubica el proyecto?
B65: Efecto Problemático Observado | H65: Altos costos de salida de la producción exportable regional
B66: Situación Problemática causante del Efecto | H66: Aeropuerto no apto para aviones de carga "grandes"
B67: Causa Principal de la Situación Problemática | H67: Deficiencias en la infraestructura de pista y de ilumnicación del aeropuerto | L67: Puesta en valor del aeropuerto por repavimentación de pista e instalación de ILS
B69: 5. ¿Por qué han seleccionado al proyecto como la alternativa elegida?
B71: La comparación con la mejora alternativa (sistema de bi-trenes) muestra que el proyecto presenta mejores indicadores de rentabilidad.
B74: 5B. ¿Cuál es la mejor alternativa que se dejó de lado por el proyecto?
B76: Aprovechar la autopista entre A y B para agregar un doble carril (de dos sentidos de circulación) e implementar un sistema de bi-trenes.
B78: 6. ¿Cuál será la capacidad prestacional del proyecto una vez finalizado?
B79: El proyecto podrá operar 5 vuelos por día, con una capacidad promedio de 100 toneladas de carga por vuelo.
...

Sheet Calendarios
A1: CALENDARIOs
A3: EX ANTE
C4: =IF($B$5=C5,1,0) -> 0 | D4: =IF($B$5=D5,1,IF(C4>=1,C4+1,0)) -> 0 | E4: =IF($B$5=E5,1,IF(D4>=1,D4+1,0)) -> 0 | F4: =IF($B$5=F5,1,IF(E4>=1,E4+1,0)) -> 0 | G4: =IF($B$5=G5,1,IF(F4>=1,F4+1,0)) -> 0 | H4: =IF($B$5=H5,1,IF(G4>=1,G4+1,0)) -> 0 | I4: =IF($B$5=I5,1,IF(H4>=1,H4+1,0)) -> 0 | J4: =IF($B$5=J5,1,IF(I4>=1,I4+1,0)) -> 0 | K4: =IF($B$5=K5,1,IF(J4>=1,J4+1,0)) -> 0 | ... YM4: =IF($B$5=YM5,1,IF(YL4>=1,YL4+1,0)) -> 0
A5: Fecha inicio | B5: =+Formulario!H140 -> 0 | C5: 36861 | D5: 36892 | E5: 36923 | F5: 36951 | G5: 36982 | H5: 37012 | I5: 37043 | J5: 37073 | K5: 37104 | L5: 37135 | M5: 37165 | N5: 37196 | O5: 37226 | P5: 37257 | Q5: 37288 | R5: 37316 | S5: 37347 | T5: 37377 | U5: 37408 | V5: 37438 | W5: 37469 | X5: 37500 | Y5: 37530 | Z5: 37561 | AA5: 37591 | AB5: 37622 | AC5: 37653 | AD5: 37681 | AE5: 37712 | AF5: 37742 | AG5: 37773 | AH5: 37803 | AI5: 37834 | AJ5: 37865 | AK5: 37895 | AL5: 37926 | AM5: 37956 | AN5: 37987 | AO5: 38018 | AP5: 38047 | AQ5: 38078 | AR5: 38108 | AS5: 38139 | AT5: 38169 | AU5: 38200 | AV5: 38231 | AW5: 38261 | AX5: 38292 | AY5: 38322 | AZ5: 38353 | BA5: 38384 | BB5: 38412 | BC5: 38443 | BD5: 38473 | BE5: 38504 | BF5: 38534 | BG5: 38565 | BH5: 38596 | BI5: 38626 | BJ5: 38657 | BK5: 38687 | BL5: 38718 | BM5: 38749 | BN5: 38777 | BO5: 38808 | BP5: 38838 | BQ5: 38869 | BR5: 38899 | BS5: 38930 | BT5: 38961 | BU5: 38991 | BV5: 39022 | BW5: 39052 | BX5: 39083 | BY5: 39114 | BZ5: 39142 | CA5: 39173 | CB5: 39203 | CC5: 39234 | CD5: 39264 | CE5: 39295 | CF5: 39326 | CG5: 39356 | CH5: 39387 | CI5: 39417 | CJ5: 39448 | CK5: 39479 | CL5: 39508 | CM5: 39539 | CN5: 39569 | CO5: 39600 | CP5: 39630 | CQ5: 39661 | CR5: 39692 | CS5: 39722 | CT5: 39753 | CU5: 39783 | CV5: 39814 | CW5: 39845 | CX5: 39873 | CY5: 39904 | CZ5: 39934 | DA5: 39965 | DB5: 39995 | DC5: 40026 | DD5: 40057 | DE5: 40087 | DF5: 40118 | DG5: 40148 | DH5: 40179 | DI5: 40210 | DJ5: 40238 | DK5: 40269 | DL5: 40299 | DM5: 40330 | DN5: 40360 | DO5: 40391 | DP5: 40422 | DQ5: 40452 | DR5: 40483 | DS5: 40513 | DT5: 40544 | DU5: 40575 | DV5: 40603 | DW5: 40634 | DX5: 40664 | DY5: 40695 | DZ5: 40725 | EA5: 40756 | EB5: 40787 | EC5: 40817 | ED5: 40848 | EE5: 40878 | EF5: 40909 | EG5: 40940 | EH5: 40969 | EI5: 41000 | EJ5: 41030 | EK5: 41061 | EL5: 41091 | EM5: 41122 | EN5: 41153 | EO5: 41183 | EP5: 41214 | EQ5: 41244 | ER5: 41275 | ES5: 41306 | ET5: 41334 | EU5: 41365 | EV5: 41395 | EW5: 41426 | EX5: 41456 | EY5: 41487 | EZ5: 41518 | FA5: 41548 | FB5: 41579 | FC5: 41609 | FD5: 41640 | FE5: 41671 | FF5: 41699 | FG5: 41730 | FH5: 41760 | FI5: 41791 | FJ5: 41821 | FK5: 41852 | FL5: 41883 | FM5: 41913 | FN5: 41944 | FO5: 41974 | FP5: 42005 | FQ5: 42036 | FR5: 42064 | FS5: 42095 | FT5: 42125 | FU5: 42156 | FV5: 42186 | FW5: 42217 | FX5: 42248 | FY5: 42278 | FZ5: 42309 | GA5: 42339 | GB5: 42370 | GC5: 42401 | GD5: 42430 | GE5: 42461 | GF5: 42491 | GG5: 42522 | GH5: 42552 | GI5: 42583 | GJ5: 42614 | GK5: 42644 | GL5: 42675 | GM5: 42705 | GN5: 42736 | GO5: 42767 | GP5: 42795 | GQ5: 42826 | GR5: 42856 | GS5: 42887 | GT5: 42917 | GU5: 42948 | GV5: 42979 | GW5: 43009 | GX5: 43040 | GY5: 43070 | GZ5: 43101 | HA5: 43132 | HB5: 43160 | HC5: 43191 | HD5: 43221 | HE5: 43252 | HF5: 43282 | HG5: 43313 | HH5: 43344 | HI5: 43374 | HJ5: 43405 | HK5: 43435 | HL5: 43466 | HM5: 43497 | HN5: 43525 | HO5: 43556 | HP5: 43586 | HQ5: 43617 | HR5: 43647 | HS5: 43678 | HT5: 43709 | HU5: 43739 | HV5: 43770 | HW5: 43800 | HX5: 43831 | HY5: 43862 | HZ5: 43891 | IA5: 43922 | IB5: 43952 | IC5: 43983 | ID5: 44013 | IE5: 44044 | IF5: 44075 | IG5: 44105 | IH5: 44136 | II5: 44166 | IJ5: 44197 | IK5: 44228 | IL5: 44256 | IM5: 44287 | IN5: 44317 | IO5: 44348 | IP5: 44378 | IQ5: 44409 | IR5: 44440 | IS5: 44470 | IT5: 44501 | IU5: 44531 | IV5: 44562 | IW5: 44593 | IX5: 44621 | IY5: 44652 | IZ5: 44682 | JA5: 44713 | JB5: 44743 | JC5: 44774 | JD5: 44805 | JE5: 44835 | JF5: 44866 | JG5: 44896 | JH5: 44927 | JI5: 44958 | JJ5: 44986 | JK5: 45017 | JL5: 45047 | JM5: 45078 | JN5: 45108 | JO5: 45139 | JP5: 45170 | JQ5: 45200 | JR5: 45231 | JS5: 45261 | JT5: 45292 | JU5: 45323 | JV5: 45352 | JW5: 45383 | JX5: 45413 | JY5: 45444 | JZ5: 45474 | KA5: 45505 | KB5: 45536 | KC5: 45566 | KD5: 45597 | KE5: 45627 | KF5: 45658 | KG5: 45689 | KH5: 45717 | KI5: 45748 | KJ5: 45778 | KK5: 45809 | KL5: 45839 | KM5: 45870 | KN5: 45901 | KO5: 45931 | KP5: 45962 | KQ5: 45992 | KR5: 46023 | KS5: 46054 | KT5: 46082 | KU5: 46113 | KV5: 46143 | KW5: 46174 | KX5: 46204 | KY5: 46235 | KZ5: 46266 | LA5: 46296 | LB5: 46327 | LC5: 46357 | LD5: 46388 | LE5: 46419 | LF5: 46447 | LG5: 46478 | LH5: 46508 | LI5: 46539 | LJ5: 46569 | LK5: 46600 | LL5: 46631 | LM5: 46661 | LN5: 46692 | LO5: 46722 | LP5: 46753 | LQ5: 46784 | LR5: 46813 | LS5: 46844 | LT5: 46874 | LU5: 46905 | LV5: 46935 | LW5: 46966 | LX5: 46997 | LY5: 47027 | LZ5: 47058 | MA5: 47088 | MB5: 47119 | MC5: 47150 | MD5: 47178 | ME5: 47209 | MF5: 47239 | MG5: 47270 | MH5: 47300 | MI5: 47331 | MJ5: 47362 | MK5: 47392 | ML5: 47423 | MM5: 47453 | MN5: 47484 | MO5: 47515 | MP5: 47543 | MQ5: 47574 | MR5: 47604 | MS5: 47635 | MT5: 47665 | MU5: 47696 | MV5: 47727 | MW5: 47757 | MX5: 47788 | MY5: 47818 | MZ5: 47849 | NA5: 47880 | NB5: 47908 | NC5: 47939 | ND5: 47969 | NE5: 48000 | NF5: 48030 | NG5: 48061 | NH5: 48092 | NI5: 48122 | NJ5: 48153 | NK5: 48183 | NL5: 48214 | NM5: 48245 | NN5: 48274 | NO5: 48305 | NP5: 48335 | NQ5: 48366 | NR5: 48396 | NS5: 48427 | NT5: 48458 | NU5: 48488 | NV5: 48519 | NW5: 48549 | NX5: 48580 | NY5: 48611 | NZ5: 48639 | OA5: 48670 | OB5: 48700 | OC5: 48731 | OD5: 48761 | OE5: 48792 | OF5: 48823 | OG5: 48853 | OH5: 48884 | OI5: 48914 | OJ5: 48945 | OK5: 48976 | OL5: 49004 | OM5: 49035 | ON5: 49065 | OO5: 49096 | OP5: 49126 | OQ5: 49157 | OR5: 49188 | OS5: 49218 | OT5: 49249 | OU5: 49279 | OV5: 49310 | OW5: 49341 | OX5: 49369 | OY5: 49400 | OZ5: 49430 | PA5: 49461 | PB5: 49491 | PC5: 49522 | PD5: 49553 | PE5: 49583 | PF5: 49614 | PG5: 49644 | PH5: 49675 | PI5: 49706 | PJ5: 49735 | PK5: 49766 | PL5: 49796 | PM5: 49827 | PN5: 49857 | PO5: 49888 | PP5: 49919 | PQ5: 49949 | PR5: 49980 | PS5: 50010 | PT5: 50041 | PU5: 50072 | PV5: 50100 | PW5: 50131 | PX5: 50161 | PY5: 50192 | PZ5: 50222 | QA5: 50253 | QB5: 50284 | QC5: 50314 | QD5: 50345 | QE5: 50375 | QF5: 50406 | QG5: 50437 | QH5: 50465 | QI5: 50496 | QJ5: 50526 | QK5: 50557 | QL5: 50587 | QM5: 50618 | QN5: 50649 | QO5: 50679 | QP5: 50710 | QQ5: 50740 | QR5: 50771 | QS5: 50802 | QT5: 50830 | QU5: 50861 | QV5: 50891 | QW5: 50922 | QX5: 50952 | QY5: 50983 | QZ5: 51014 | RA5: 51044 | RB5: 51075 | RC5: 51105 | RD5: 51136 | RE5: 51167 | RF5: 51196 | RG5: 51227 | RH5: 51257 | RI5: 51288 | RJ5: 51318 | RK5: 51349 | RL5: 51380 | RM5: 51410 | RN5: 51441 | RO5: 51471 | RP5: 51502 | RQ5: 51533 | RR5: 51561 | RS5: 51592 | RT5: 51622 | RU5: 51653 | RV5: 51683 | RW5: 51714 | RX5: 51745 | RY5: 51775 | RZ5: 51806 | SA5: 51836 | SB5: 51867 | SC5: 51898 | SD5: 51926 | SE5: 51957 | SF5: 51987 | SG5: 52018 | SH5: 52048 | SI5: 52079 | SJ5: 52110 | SK5: 52140 | SL5: 52171 | SM5: 52201 | SN5: 52232 | SO5: 52263 | SP5: 52291 | SQ5: 52322 | SR5: 52352 | SS5: 52383 | ST5: 52413 | SU5: 52444 | SV5: 52475 | SW5: 52505 | SX5: 52536 | SY5: 52566 | SZ5: 52597 | TA5: 52628 | TB5: 52657 | TC5: 52688 | TD5: 52718 | TE5: 52749 | TF5: 52779 | TG5: 52810 | TH5: 52841 | TI5: 52871 | TJ5: 52902 | TK5: 52932 | TL5: 52963 | TM5: 52994 | TN5: 53022 | TO5: 53053 | TP5: 53083 | TQ5: 53114 | TR5: 53144 | TS5: 53175 | TT5: 53206 | TU5: 53236 | TV5: 53267 | TW5: 53297 | TX5: 53328 | TY5: 53359 | TZ5: 53387 | UA5: 53418 | UB5: 53448 | UC5: 53479 | UD5: 53509 | UE5: 53540 | UF5: 53571 | UG5: 53601 | UH5: 53632 | UI5: 53662 | UJ5: 53693 | UK5: 53724 | UL5: 53752 | UM5: 53783 | UN5: 53813 | UO5: 53844 | UP5: 53874 | UQ5: 53905 | UR5: 53936 | US5: 53966 | UT5: 53997 | UU5: 54027 | UV5: 54058 | UW5: 54089 | UX5: 54118 | UY5: 54149 | UZ5: 54179 | VA5: 54210 | VB5: 54240 | VC5: 54271 | VD5: 54302 | VE5: 54332 | VF5: 54363 | VG5: 54393 | VH5: 54424 | VI5: 54455 | VJ5: 54483 | VK5: 54514 | VL5: 54544 | VM5: 54575 | VN5: 54605 | VO5: 54636 | VP5: 54667 | VQ5: 54697 | VR5: 54728 | VS5: 54758 | VT5: 54789 | VU5: 54820 | VV5: 54848 | VW5: 54879 | VX5: 54909 | VY5: 54940 | VZ5: 54970 | WA5: 55001 | WB5: 55032 | WC5: 55062 | WD5: 55093 | WE5: 55123 | WF5: 55154 | WG5: 55185 | WH5: 55213 | WI5: 55244 | WJ5: 55274 | WK5: 55305 | WL5: 55335 | WM5: 55366 | WN5: 55397 | WO5: 55427 | WP5: 55458 | WQ5: 55488 | WR5: 55519 | WS5: 55550 | WT5: 55579 | WU5: 55610 | WV5: 55640 | WW5: 55671 | WX5: 55701 | WY5: 55732 | WZ5: 55763 | XA5: 55793 | XB5: 55824 | XC5: 55854 | XD5: 55885 | XE5: 55916 | XF5: 55944 | XG5: 55975 | XH5: 56005 | XI5: 56036 | XJ5: 56066 | XK5: 56097 | XL5: 56128 | XM5: 56158 | XN5: 56189 | XO5: 56219 | XP5: 56250 | XQ5: 56281 | XR5: 56309 | XS5: 56340 | XT5: 56370 | XU5: 56401 | XV5: 56431 | XW5: 56462 | XX5: 56493 | XY5: 56523 | XZ5: 56554 | YA5: 56584 | YB5: 56615 | YC5: 56646 | YD5: 56674 | YE5: 56705 | YF5: 56735 | YG5: 56766 | YH5: 56796 | YI5: 56827 | YJ5: 56858 | YK5: 56888 | YL5: 56919 | YM5: 56949
C6: =IF(C7<$B$13,0,B6+1) -> 1 | D6: =IF(D7<$B$13,0,C6+1) -> 2 | E6: =IF(E7<$B$13,0,D6+1) -> 3 | F6: =IF(F7<$B$13,0,E6+1) -> 4 | G6: =IF(G7<$B$13,0,F6+1) -> 5 | H6: =IF(H7<$B$13,0,G6+1) -> 6 | I6: =IF(I7<$B$13,0,H6+1) -> 7 | J6: =IF(J7<$B$13,0,I6+1) -> 8 | ... YM6: =IF(YM7<$B$13,0,YL6+1) -> 661
A7: Fecha de cierre | B7: =+Formulario!H142 -> 0 | C7: 36891 | D7: 36922 | E7: 36950 | F7: 36981 | G7: 37011 | H7: 37042 | I7: 37072 | J7: 37103 | K7: 37134 | L7: 37164 | M7: 37195 | N7: 37225 | O7: 37256 | P7: 37287 | Q7: 37315 | R7: 37346 | S7: 37376 | T7: 37407 | U7: 37437 | V7: 37468 | W7: 37499 | X7: 37529 | Y7: 37560 | Z7: 37590 | AA7: 37621 | AB7: 37652 | AC7: 37680 | AD7: 37711 | AE7: 37741 | AF7: 37772 | AG7: 37802 | AH7: 37833 | AI7: 37864 | AJ7: 37894 | AK7: 37925 | AL7: 37955 | AM7: 37986 | AN7: 38017 | AO7: 38046 | AP7: 38077 | AQ7: 38107 | AR7: 38138 | AS7: 38168 | AT7: 38199 | AU7: 38230 | AV7: 38260 | AW7: 38291 | AX7: 38321 | AY7: 38352 | AZ7: 38383 | BA7: 38411 | BB7: 38442 | BC7: 38472 | BD7: 38503 | BE7: 38533 | BF7: 38564 | BG7: 38595 | BH7: 38625 | BI7: 38656 | BJ7: 38686 | BK7: 38717 | BL7: 38748 | BM7: 38776 | BN7: 38807 | BO7: 38837 | BP7: 38868 | BQ7: 38898 | BR7: 38929 | BS7: 38960 | BT7: 38990 | BU7: 39021 | BV7: 39051 | BW7: 39082 | BX7: 39113 | BY7: 39141 | BZ7: 39172 | CA7: 39202 | CB7: 39233 | CC7: 39263 | CD7: 39294 | CE7: 39325 | CF7: 39355 | CG7: 39386 | CH7: 39416 | CI7: 39447 | CJ7: 39478 | CK7: 39507 | CL7: 39538 | CM7: 39568 | CN7: 39599 | CO7: 39629 | CP7: 39660 | CQ7: 39691 | CR7: 39721 | CS7: 39752 | CT7: 39782 | CU7: 39813 | CV7: 39844 | CW7: 39872 | CX7: 39903 | CY7: 39933 | CZ7: 39964 | DA7: 39994 | DB7: 40025 | DC7: 40056 | DD7: 40086 | DE7: 40117 | DF7: 40147 | DG7: 40178 | DH7: 40209 | DI7: 40237 | DJ7: 40268 | DK7: 40298 | DL7: 40329 | DM7: 40359 | DN7: 40390 | DO7: 40421 | DP7: 40451 | DQ7: 40482 | DR7: 40512 | DS7: 40543 | DT7: 40574 | DU7: 40602 | DV7: 40633 | DW7: 40663 | DX7: 40694 | DY7: 40724 | DZ7: 40755 | EA7: 40786 | EB7: 40816 | EC7: 40847 | ED7: 40877 | EE7: 40908 | EF7: 40939 | EG7: 40968 | EH7: 40999 | EI7: 41029 | EJ7: 41060 | EK7: 41090 | EL7: 41121 | EM7: 41152 | EN7: 41182 | EO7: 41213 | EP7: 41243 | EQ7: 41274 | ER7: 41305 | ES7: 41333 | ET7: 41364 | EU7: 41394 | EV7: 41425 | EW7: 41455 | EX7: 41486 | EY7: 41517 | EZ7: 41547 | FA7: 41578 | FB7: 41608 | FC7: 41639 | FD7: 41670 | FE7: 41698 | FF7: 41729 | FG7: 41759 | FH7: 41790 | FI7: 41820 | FJ7: 41851 | FK7: 41882 | FL7: 41912 | FM7: 41943 | FN7: 41973 | FO7: 42004 | FP7: 42035 | FQ7: 42063 | FR7: 42094 | FS7: 42124 | FT7: 42155 | FU7: 42185 | FV7: 42216 | FW7: 42247 | FX7: 42277 | FY7: 42308 | FZ7: 42338 | GA7: 42369 | GB7: 42400 | GC7: 42429 | GD7: 42460 | GE7: 42490 | GF7: 42521 | GG7: 42551 | GH7: 42582 | GI7: 42613 | GJ7: 42643 | GK7: 42674 | GL7: 42704 | GM7: 42735 | GN7: 42766 | GO7: 42794 | GP7: 42825 | GQ7: 42855 | GR7: 42886 | GS7: 42916 | GT7: 42947 | GU7: 42978 | GV7: 43008 | GW7: 43039 | GX7: 43069 | GY7: 43100 | GZ7: 43131 | HA7: 43159 | HB7: 43190 | HC7: 43220 | HD7: 43251 | HE7: 43281 | HF7: 43312 | HG7: 43343 | HH7: 43373 | HI7: 43404 | HJ7: 43434 | HK7: 43465 | HL7: 43496 | HM7: 43524 | HN7: 43555 | HO7: 43585 | HP7: 43616 | HQ7: 43646 | HR7: 43677 | HS7: 43708 | HT7: 43738 | HU7: 43769 | HV7: 43799 | HW7: 43830 | HX7: 43861 | HY7: 43890 | HZ7: 43921 | IA7: 43951 | IB7: 43982 | IC7: 44012 | ID7: 44043 | IE7: 44074 | IF7: 44104 | IG7: 44135 | IH7: 44165 | II7: 44196 | IJ7: 44227 | IK7: 44255 | IL7: 44286 | IM7: 44316 | IN7: 44347 | IO7: 44377 | IP7: 44408 | IQ7: 44439 | IR7: 44469 | IS7: 44500 | IT7: 44530 | IU7: 44561 | IV7: 44592 | IW7: 44620 | IX7: 44651 | IY7: 44681 | IZ7: 44712 | JA7: 44742 | JB7: 44773 | JC7: 44804 | JD7: 44834 | JE7: 44865 | JF7: 44895 | JG7: 44926 | JH7: 44957 | JI7: 44985 | JJ7: 45016 | JK7: 45046 | JL7: 45077 | JM7: 45107 | JN7: 45138 | JO7: 45169 | JP7: 45199 | JQ7: 45230 | JR7: 45260 | JS7: 45291 | JT7: 45322 | JU7: 45351 | JV7: 45382 | JW7: 45412 | JX7: 45443 | JY7: 45473 | JZ7: 45504 | KA7: 45535 | KB7: 45565 | KC7: 45596 | KD7: 45626 | KE7: 45657 | KF7: 45688 | KG7: 45716 | KH7: 45747 | KI7: 45777 | KJ7: 45808 | KK7: 45838 | KL7: 45869 | KM7: 45900 | KN7: 45930 | KO7: 45961 | KP7: 45991 | KQ7: 46022 | KR7: 46053 | KS7: 46081 | KT7: 46112 | KU7: 46142 | KV7: 46173 | KW7: 46203 | KX7: 46234 | KY7: 46265 | KZ7: 46295 | LA7: 46326 | LB7: 46356 | LC7: 46387 | LD7: 46418 | LE7: 46446 | LF7: 46477 | LG7: 46507 | LH7: 46538 | LI7: 46568 | LJ7: 46599 | LK7: 46630 | LL7: 46660 | LM7: 46691 | LN7: 46721 | LO7: 46752 | LP7: 46783 | LQ7: 46812 | LR7: 46843 | LS7: 46873 | LT7: 46904 | LU7: 46934 | LV7: 46965 | LW7: 46996 | LX7: 47026 | LY7: 47057 | LZ7: 47087 | MA7: 47118 | MB7: 47149 | MC7: 47177 | MD7: 47208 | ME7: 47238 | MF7: 47269 | MG7: 47299 | MH7: 47330 | MI7: 47361 | MJ7: 47391 | MK7: 47422 | ML7: 47452 | MM7: 47483 | MN7: 47514 | MO7: 47542 | MP7: 47573 | MQ7: 47603 | MR7: 47634 | MS7: 47664 | MT7: 47695 | MU7: 47726 | MV7: 47756 | MW7: 47787 | MX7: 47817 | MY7: 47848 | MZ7: 47879 | NA7: 47907 | NB7: 47938 | NC7: 47968 | ND7: 47999 | NE7: 48029 | NF7: 48060 | NG7: 48091 | NH7: 48121 | NI7: 48152 | NJ7: 48182 | NK7: 48213 | NL7: 48244 | NM7: 48273 | NN7: 48304 | NO7: 48334 | NP7: 48365 | NQ7: 48395 | NR7: 48426 | NS7: 48457 | NT7: 48487 | NU7: 48518 | NV7: 48548 | NW7: 48579 | NX7: 48610 | NY7: 48638 | NZ7: 48669 | OA7: 48699 | OB7: 48730 | OC7: 48760 | OD7: 48791 | OE7: 48822 | OF7: 48852 | OG7: 48883 | OH7: 48913 | OI7: 48944 | OJ7: 48975 | OK7: 49003 | OL7: 49034 | OM7: 49064 | ON7: 49095 | OO7: 49125 | OP7: 49156 | OQ7: 49187 | OR7: 49217 | OS7: 49248 | OT7: 49278 | OU7: 49309 | OV7: 49340 | OW7: 49368 | OX7: 49399 | OY7: 49429 | OZ7: 49460 | PA7: 49490 | PB7: 49521 | PC7: 49552 | PD7: 49582 | PE7: 49613 | PF7: 49643 | PG7: 49674 | PH7: 49705 | PI7: 49734 | PJ7: 49765 | PK7: 49795 | PL7: 49826 | PM7: 49856 | PN7: 49887 | PO7: 49918 | PP7: 49948 | PQ7: 49979 | PR7: 50009 | PS7: 50040 | PT7: 50071 | PU7: 50099 | PV7: 50130 | PW7: 50160 | PX7: 50191 | PY7: 50221 | PZ7: 50252 | QA7: 50283 | QB7: 50313 | QC7: 50344 | QD7: 50374 | QE7: 50405 | QF7: 50436 | QG7: 50464 | QH7: 50495 | QI7: 50525 | QJ7: 50556 | QK7: 50586 | QL7: 50617 | QM7: 50648 | QN7: 50678 | QO7: 50709 | QP7: 50739 | QQ7: 50770 | QR7: 50801 | QS7: 50829 | QT7: 50860 | QU7: 50890 | QV7: 50921 | QW7: 50951 | QX7: 50982 | QY7: 51013 | QZ7: 51043 | RA7: 51074 | RB7: 51104 | RC7: 51135 | RD7: 51166 | RE7: 51195 | RF7: 51226 | RG7: 51256 | RH7: 51287 | RI7: 51317 | RJ7: 51348 | RK7: 51379 | RL7: 51409 | RM7: 51440 | RN7: 51470 | RO7: 51501 | RP7: 51532 | RQ7: 51560 | RR7: 51591 | RS7: 51621 | RT7: 51652 | RU7: 51682 | RV7: 51713 | RW7: 51744 | RX7: 51774 | RY7: 51805 | RZ7: 51835 | SA7: 51866 | SB7: 51897 | SC7: 51925 | SD7: 51956 | SE7: 51986 | SF7: 52017 | SG7: 52047 | SH7: 52078 | SI7: 52109 | SJ7: 52139 | SK7: 52170 | SL7: 52200 | SM7: 52231 | SN7: 52262 | SO7: 52290 | SP7: 52321 | SQ7: 52351 | SR7: 52382 | SS7: 52412 | ST7: 52443 | SU7: 52474 | SV7: 52504 | SW7: 52535 | SX7: 52565 | SY7: 52596 | SZ7: 52627 | TA7: 52656 | TB7: 52687 | TC7: 52717 | TD7: 52748 | TE7: 52778 | TF7: 52809 | TG7: 52840 | TH7: 52870 | TI7: 52901 | TJ7: 52931 | TK7: 52962 | TL7: 52993 | TM7: 53021 | TN7: 53052 | TO7: 53082 | TP7: 53113 | TQ7: 53143 | TR7: 53174 | TS7: 53205 | TT7: 53235 | TU7: 53266 | TV7: 53296 | TW7: 53327 | TX7: 53358 | TY7: 53386 | TZ7: 53417 | UA7: 53447 | UB7: 53478 | UC7: 53508 | UD7: 53539 | UE7: 53570 | UF7: 53600 | UG7: 53631 | UH7: 53661 | UI7: 53692 | UJ7: 53723 | UK7: 53751 | UL7: 53782 | UM7: 53812 | UN7: 53843 | UO7: 53873 | UP7: 53904 | UQ7: 53935 | UR7: 53965 | US7: 53996 | UT7: 54026 | UU7: 54057 | UV7: 54088 | UW7: 54117 | UX7: 54148 | UY7: 54178 | UZ7: 54209 | VA7: 54239 | VB7: 54270 | VC7: 54301 | VD7: 54331 | VE7: 54362 | VF7: 54392 | VG7: 54423 | VH7: 54454 | VI7: 54482 | VJ7: 54513 | VK7: 54543 | VL7: 54574 | VM7: 54604 | VN7: 54635 | VO7: 54666 | VP7: 54696 | VQ7: 54727 | VR7: 54757 | VS7: 54788 | VT7: 54819 | VU7: 54847 | VV7: 54878 | VW7: 54908 | VX7: 54939 | VY7: 54969 | VZ7: 55000 | WA7: 55031 | WB7: 55061 | WC7: 55092 | WD7: 55122 | WE7: 55153 | WF7: 55184 | WG7: 55212 | WH7: 55243 | WI7: 55273 | WJ7: 55304 | WK7: 55334 | WL7: 55365 | WM7: 55396 | WN7: 55426 | WO7: 55457 | WP7: 55487 | WQ7: 55518 | WR7: 55549 | WS7: 55578 | WT7: 55609 | WU7: 55639 | WV7: 55670 | WW7: 55700 | WX7: 55731 | WY7: 55762 | WZ7: 55792 | XA7: 55823 | XB7: 55853 | XC7: 55884 | XD7: 55915 | XE7: 55943 | XF7: 55974 | XG7: 56004 | XH7: 56035 | XI7: 56065 | XJ7: 56096 | XK7: 56127 | XL7: 56157 | XM7: 56188 | XN7: 56218 | XO7: 56249 | XP7: 56280 | XQ7: 56308 | XR7: 56339 | XS7: 56369 | XT7: 56400 | XU7: 56430 | XV7: 56461 | XW7: 56492 | XX7: 56522 | XY7: 56553 | XZ7: 56583 | YA7: 56614 | YB7: 56645 | YC7: 56673 | YD7: 56704 | YE7: 56734 | YF7: 56765 | YG7: 56795 | YH7: 56826 | YI7: 56857 | YJ7: 56887 | YK7: 56918 | YL7: 56948 | YM7: 56979
A9: EX POST
C10: =IF($B$11=C11,1,0) -> 0 | D10: =IF($B$11=D11,1,IF(C10>=1,C10+1,0)) -> 0 | E10: =IF($B$11=E11,1,IF(D10>=1,D10+1,0)) -> 0 | F10: =IF($B$11=F11,1,IF(E10>=1,E10+1,0)) -> 0 | G10: =IF($B$11=G11,1,IF(F10>=1,F10+1,0)) -> 0 | H10: =IF($B$11=H11,1,IF(G10>=1,G10+1,0)) -> 0 | I10: =IF($B$11=I11,1,IF(H10>=1,H10+1,0)) -> 0 | J10: =IF($B$11=J11,1,IF(I10>=1,I10+1,0)) -> 0 | K10: =IF($B$11=K11,1,IF(J10>=1,J10+1,0)) -> 0 | ... YM10: =IF($B$11=YM11,1,IF(YL10>=1,YL10+1,0)) -> 0
A11: Fecha inicio | B11: =+Formulario!H308 -> 0 | C11: 36861 | D11: 36892 | E11: 36923 | F11: 36951 | G11: 36982 | H11: 37012 | I11: 37043 | J11: 37073 | K11: 37104 | L11: 37135 | M11: 37165 | N11: 37196 | O11: 37226 | P11: 37257 | Q11: 37288 | R11: 37316 | S11: 37347 | T11: 37377 | U11: 37408 | V11: 37438 | W11: 37469 | X11: 37500 | Y11: 37530 | Z11: 37561 | AA11: 37591 | AB11: 37622 | AC11: 37653 | AD11: 37681 | AE11: 37712 | AF11: 37742 | AG11: 37773 | AH11: 37803 | AI11: 37834 | AJ11: 37865 | AK11: 37895 | AL11: 37926 | AM11: 37956 | AN11: 37987 | AO11: 38018 | AP11: 38047 | AQ11: 38078 | AR11: 38108 | AS11: 38139 | AT11: 38169 | AU11: 38200 | AV11: 38231 | AW11: 38261 | AX11: 38292 | AY11: 38322 | AZ11: 38353 | BA11: 38384 | BB11: 38412 | BC11: 38443 | BD11: 38473 | BE11: 38504 | BF11: 38534 | BG11: 38565 | BH11: 38596 | BI11: 38626 | BJ11: 38657 | BK11: 38687 | BL11: 38718 | BM11: 38749 | BN11: 38777 | BO11: 38808 | BP11: 38838 | BQ11: 38869 | BR11: 38899 | BS11: 38930 | BT11: 38961 | BU11: 38991 | BV11: 39022 | BW11: 39052 | BX11: 39083 | BY11: 39114 | BZ11: 39142 | CA11: 39173 | CB11: 39203 | CC11: 39234 | CD11: 39264 | CE11: 39295 | CF11: 39326 | CG11: 39356 | CH11: 39387 | CI11: 39417 | CJ11: 39448 | CK11: 39479 | CL11: 39508 | CM11: 39539 | CN11: 39569 | CO11: 39600 | CP11: 39630 | CQ11: 39661 | CR11: 39692 | CS11: 39722 | CT11: 39753 | CU11: 39783 | CV11: 39814 | CW11: 39845 | CX11: 39873 | CY11: 39904 | CZ11: 39934 | DA11: 39965 | DB11: 39995 | DC11: 40026 | DD11: 40057 | DE11: 40087 | DF11: 40118 | DG11: 40148 | DH11: 40179 | DI11: 40210 | DJ11: 40238 | DK11: 40269 | DL11: 40299 | DM11: 40330 | DN11: 40360 | DO11: 40391 | DP11: 40422 | DQ11: 40452 | DR11: 40483 | DS11: 40513 | DT11: 40544 | DU11: 40575 | DV11: 40603 | DW11: 40634 | DX11: 40664 | DY11: 40695 | DZ11: 40725 | EA11: 40756 | EB11: 40787 | EC11: 40817 | ED11: 40848 | EE11: 40878 | EF11: 40909 | EG11: 40940 | EH11: 40969 | EI11: 41000 | EJ11: 41030 | EK11: 41061 | EL11: 41091 | EM11: 41122 | EN11: 41153 | EO11: 41183 | EP11: 41214 | EQ11: 41244 | ER11: 41275 | ES11: 41306 | ET11: 41334 | EU11: 41365 | EV11: 41395 | EW11: 41426 | EX11: 41456 | EY11: 41487 | EZ11: 41518 | FA11: 41548 | FB11: 41579 | FC11: 41609 | FD11: 41640 | FE11: 41671 | FF11: 41699 | FG11: 41730 | FH11: 41760 | FI11: 41791 | FJ11: 41821 | FK11: 41852 | FL11: 41883 | FM11: 41913 | FN11: 41944 | FO11: 41974 | FP11: 42005 | FQ11: 42036 | FR11: 42064 | FS11: 42095 | FT11: 42125 | FU11: 42156 | FV11: 42186 | FW11: 42217 | FX11: 42248 | FY11: 42278 | FZ11: 42309 | GA11: 42339 | GB11: 42370 | GC11: 42401 | GD11: 42430 | GE11: 42461 | GF11: 42491 | GG11: 42522 | GH11: 42552 | GI11: 42583 | GJ11: 42614 | GK11: 42644 | GL11: 42675 | GM11: 42705 | GN11: 42736 | GO11: 42767 | GP11: 42795 | GQ11: 42826 | GR11: 42856 | GS11: 42887 | GT11: 42917 | GU11: 42948 | GV11: 42979 | GW11: 43009 | GX11: 43040 | GY11: 43070 | GZ11: 43101 | HA11: 43132 | HB11: 43160 | HC11: 43191 | HD11: 43221 | HE11: 43252 | HF11: 43282 | HG11: 43313 | HH11: 43344 | HI11: 43374 | HJ11: 43405 | HK11: 43435 | HL11: 43466 | HM11: 43497 | HN11: 43525 | HO11: 43556 | HP11: 43586 | HQ11: 43617 | HR11: 43647 | HS11: 43678 | HT11: 43709 | HU11: 43739 | HV11: 43770 | HW11: 43800 | HX11: 43831 | HY11: 43862 | HZ11: 43891 | IA11: 43922 | IB11: 43952 | IC11: 43983 | ID11: 44013 | IE11: 44044 | IF11: 44075 | IG11: 44105 | IH11: 44136 | II11: 44166 | IJ11: 44197 | IK11: 44228 | IL11: 44256 | IM11: 44287 | IN11: 44317 | IO11: 44348 | IP11: 44378 | IQ11: 44409 | IR11: 44440 | IS11: 44470 | IT11: 44501 | IU11: 44531 | IV11: 44562 | IW11: 44593 | IX11: 44621 | IY11: 44652 | IZ11: 44682 | JA11: 44713 | JB11: 44743 | JC11: 44774 | JD11: 44805 | JE11: 44835 | JF11: 44866 | JG11: 44896 | JH11: 44927 | JI11: 44958 | JJ11: 44986 | JK11: 45017 | JL11: 45047 | JM11: 45078 | JN11: 45108 | JO11: 45139 | JP11: 45170 | JQ11: 45200 | JR11: 45231 | JS11: 45261 | JT11: 45292 | JU11: 45323 | JV11: 45352 | JW11: 45383 | JX11: 45413 | JY11: 45444 | JZ11: 45474 | KA11: 45505 | KB11: 45536 | KC11: 45566 | KD11: 45597 | KE11: 45627 | KF11: 45658 | KG11: 45689 | KH11: 45717 | KI11: 45748 | KJ11: 45778 | KK11: 45809 | KL11: 45839 | KM11: 45870 | KN11: 45901 | KO11: 45931 | KP11: 45962 | KQ11: 45992 | KR11: 46023 | KS11: 46054 | KT11: 46082 | KU11: 46113 | KV11: 46143 | KW11: 46174 | KX11: 46204 | KY11: 46235 | KZ11: 46266 | LA11: 46296 | LB11: 46327 | LC11: 46357 | LD11: 46388 | LE11: 46419 | LF11: 46447 | LG11: 46478 | LH11: 46508 | LI11: 46539 | LJ11: 46569 | LK11: 46600 | LL11: 46631 | LM11: 46661 | LN11: 46692 | LO11: 46722 | LP11: 46753 | LQ11: 46784 | LR11: 46813 | LS11: 46844 | LT11: 46874 | LU11: 46905 | LV11: 46935 | LW11: 46966 | LX11: 46997 | LY11: 47027 | LZ11: 47058 | MA11: 47088 | MB11: 47119 | MC11: 47150 | MD11: 47178 | ME11: 47209 | MF11: 47239 | MG11: 47270 | MH11: 47300 | MI11: 47331 | MJ11: 47362 | MK11: 47392 | ML11: 47423 | MM11: 47453 | MN11: 47484 | MO11: 47515 | MP11: 47543 | MQ11: 47574 | MR11: 47604 | MS11: 47635 | MT11: 47665 | MU11: 47696 | MV11: 47727 | MW11: 47757 | MX11: 47788 | MY11: 47818 | MZ11: 47849 | NA11: 47880 | NB11: 47908 | NC11: 47939 | ND11: 47969 | NE11: 48000 | NF11: 48030 | NG11: 48061 | NH11: 48092 | NI11: 48122 | NJ11: 48153 | NK11: 48183 | NL11: 48214 | NM11: 48245 | NN11: 48274 | NO11: 48305 | NP11: 48335 | NQ11: 48366 | NR11: 48396 | NS11: 48427 | NT11: 48458 | NU11: 48488 | NV11: 48519 | NW11: 48549 | NX11: 48580 | NY11: 48611 | NZ11: 48639 | OA11: 48670 | OB11: 48700 | OC11: 48731 | OD11: 48761 | OE11: 48792 | OF11: 48823 | OG11: 48853 | OH11: 48884 | OI11: 48914 | OJ11: 48945 | OK11: 48976 | OL11: 49004 | OM11: 49035 | ON11: 49065 | OO11: 49096 | OP11: 49126 | OQ11: 49157 | OR11: 49188 | OS11: 49218 | OT11: 49249 | OU11: 49279 | OV11: 49310 | OW11: 49341 | OX11: 49369 | OY11: 49400 | OZ11: 49430 | PA11: 49461 | PB11: 49491 | PC11: 49522 | PD11: 49553 | PE11: 49583 | PF11: 49614 | PG11: 49644 | PH11: 49675 | PI11: 49706 | PJ11: 49735 | PK11: 49766 | PL11: 49796 | PM11: 49827 | PN11: 49857 | PO11: 49888 | PP11: 49919 | PQ11: 49949 | PR11: 49980 | PS11: 50010 | PT11: 50041 | PU11: 50072 | PV11: 50100 | PW11: 50131 | PX11: 50161 | PY11: 50192 | PZ11: 50222 | QA11: 50253 | QB11: 50284 | QC11: 50314 | QD11: 50345 | QE11: 50375 | QF11: 50406 | QG11: 50437 | QH11: 50465 | QI11: 50496 | QJ11: 50526 | QK11: 50557 | QL11: 50587 | QM11: 50618 | QN11: 50649 | QO11: 50679 | QP11: 50710 | QQ11: 50740 | QR11: 50771 | QS11: 50802 | QT11: 50830 | QU11: 50861 | QV11: 50891 | QW11: 50922 | QX11: 50952 | QY11: 50983 | QZ11: 51014 | RA11: 51044 | RB11: 51075 | RC11: 51105 | RD11: 51136 | RE11: 51167 | RF11: 51196 | RG11: 51227 | RH11: 51257 | RI11: 51288 | RJ11: 51318 | RK11: 51349 | RL11: 51380 | RM11: 51410 | RN11: 51441 | RO11: 51471 | RP11: 51502 | RQ11: 51533 | RR11: 51561 | RS11: 51592 | RT11: 51622 | RU11: 51653 | RV11: 51683 | RW11: 51714 | RX11: 51745 | RY11: 51775 | RZ11: 51806 | SA11: 51836 | SB11: 51867 | SC11: 51898 | SD11: 51926 | SE11: 51957 | SF11: 51987 | SG11: 52018 | SH11: 52048 | SI11: 52079 | SJ11: 52110 | SK11: 52140 | SL11: 52171 | SM11: 52201 | SN11: 52232 | SO11: 52263 | SP11: 52291 | SQ11: 52322 | SR11: 52352 | SS11: 52383 | ST11: 52413 | SU11: 52444 | SV11: 52475 | SW11: 52505 | SX11: 52536 | SY11: 52566 | SZ11: 52597 | TA11: 52628 | TB11: 52657 | TC11: 52688 | TD11: 52718 | TE11: 52749 | TF11: 52779 | TG11: 52810 | TH11: 52841 | TI11: 52871 | TJ11: 52902 | TK11: 52932 | TL11: 52963 | TM11: 52994 | TN11: 53022 | TO11: 53053 | TP11: 53083 | TQ11: 53114 | TR11: 53144 | TS11: 53175 | TT11: 53206 | TU11: 53236 | TV11: 53267 | TW11: 53297 | TX11: 53328 | TY11: 53359 | TZ11: 53387 | UA11: 53418 | UB11: 53448 | UC11: 53479 | UD11: 53509 | UE11: 53540 | UF11: 53571 | UG11: 53601 | UH11: 53632 | UI11: 53662 | UJ11: 53693 | UK11: 53724 | UL11: 53752 | UM11: 53783 | UN11: 53813 | UO11: 53844 | UP11: 53874 | UQ11: 53905 | UR11: 53936 | US11: 53966 | UT11: 53997 | UU11: 54027 | UV11: 54058 | UW11: 54089 | UX11: 54118 | UY11: 54149 | UZ11: 54179 | VA11: 54210 | VB11: 54240 | VC11: 54271 | VD11: 54302 | VE11: 54332 | VF11: 54363 | VG11: 54393 | VH11: 54424 | VI11: 54455 | VJ11: 54483 | VK11: 54514 | VL11: 54544 | VM11: 54575 | VN11: 54605 | VO11: 54636 | VP11: 54667 | VQ11: 54697 | VR11: 54728 | VS11: 54758 | VT11: 54789 | VU11: 54820 | VV11: 54848 | VW11: 54879 | VX11: 54909 | VY11: 54940 | VZ11: 54970 | WA11: 55001 | WB11: 55032 | WC11: 55062 | WD11: 55093 | WE11: 55123 | WF11: 55154 | WG11: 55185 | WH11: 55213 | WI11: 55244 | WJ11: 55274 | WK11: 55305 | WL11: 55335 | WM11: 55366 | WN11: 55397 | WO11: 55427 | WP11: 55458 | WQ11: 55488 | WR11: 55519 | WS11: 55550 | WT11: 55579 | WU11: 55610 | WV11: 55640 | WW11: 55671 | WX11: 55701 | WY11: 55732 | WZ11: 55763 | XA11: 55793 | XB11: 55824 | XC11: 55854 | XD11: 55885 | XE11: 55916 | XF11: 55944 | XG11: 55975 | XH11: 56005 | XI11: 56036 | XJ11: 56066 | XK11: 56097 | XL11: 56128 | XM11: 56158 | XN11: 56189 | XO11: 56219 | XP11: 56250 | XQ11: 56281 | XR11: 56309 | XS11: 56340 | XT11: 56370 | XU11: 56401 | XV11: 56431 | XW11: 56462 | XX11: 56493 | XY11: 56523 | XZ11: 56554 | YA11: 56584 | YB11: 56615 | YC11: 56646 | YD11: 56674 | YE11: 56705 | YF11: 56735 | YG11: 56766 | YH11: 56796 | YI11: 56827 | YJ11: 56858 | YK11: 56888 | YL11: 56919 | YM11: 56949
C12: =IF(C13<$B$13,0,B12+1) -> 1 | D12: =IF(D13<$B$13,0,C12+1) -> 2 | E12: =IF(E13<$B$13,0,D12+1) -> 3 | F12: =IF(F13<$B$13,0,E12+1) -> 4 | G12: =IF(G13<$B$13,0,F12+1) -> 5 | H12: =IF(H13<$B$13,0,G12+1) -> 6 | I12: =IF(I13<$B$13,0,H12+1) -> 7 | J12: =IF(J13<$B$13,0,I12+1) -> 8 | ... YM12: =IF(YM13<$B$13,0,YL12+1) -> 661
A13: Fecha de cierre | B13: =+Formulario!H310 -> 0 | C13: 36891 | D13: 36922 | E13: 36950 | F13: 36981 | G13: 37011 | H13: 37042 | I13: 37072 | J13: 37103 | K13: 37134 | L13: 37164 | M13: 37195 | N13: 37225 | O13: 37256 | P13: 37287 | Q13: 37315 | R13: 37346 | S13: 37376 | T13: 37407 | U13: 37437 | V13: 37468 | W13: 37499 | X13: 37529 | Y13: 37560 | Z13: 37590 | AA13: 37621 | AB13: 37652 | AC13: 37680 | AD13: 37711 | AE13: 37741 | AF13: 37772 | AG13: 37802 | AH13: 37833 | AI13: 37864 | AJ13: 37894 | AK13: 37925 | AL13: 37955 | AM13: 37986 | AN13: 38017 | AO13: 38046 | AP13: 38077 | AQ13: 38107 | AR13: 38138 | AS13: 38168 | AT13: 38199 | AU13: 38230 | AV13: 38260 | AW13: 38291 | AX13: 38321 | AY13: 38352 | AZ13: 38383 | BA13: 38411 | BB13: 38442 | BC13: 38472 | BD13: 38503 | BE13: 38533 | BF13: 38564 | BG13: 38595 | BH13: 38625 | BI13: 38656 | BJ13: 38686 | BK13: 38717 | BL13: 38748 | BM13: 38776 | BN13: 38807 | BO13: 38837 | BP13: 38868 | BQ13: 38898 | BR13: 38929 | BS13: 38960 | BT13: 38990 | BU13: 39021 | BV13: 39051 | BW13: 39082 | BX13: 39113 | BY13: 39141 | BZ13: 39172 | CA13: 39202 | CB13: 39233 | CC13: 39263 | CD13: 39294 | CE13: 39325 | CF13: 39355 | CG13: 39386 | CH13: 39416 | CI13: 39447 | CJ13: 39478 | CK13: 39507 | CL13: 39538 | CM13: 39568 | CN13: 39599 | CO13: 39629 | CP13: 39660 | CQ13: 39691 | CR13: 39721 | CS13: 39752 | CT13: 39782 | CU13: 39813 | CV13: 39844 | CW13: 39872 | CX13: 39903 | CY13: 39933 | CZ13: 39964 | DA13: 39994 | DB13: 40025 | DC13: 40056 | DD13: 40086 | DE13: 40117 | DF13: 40147 | DG13: 40178 | DH13: 40209 | DI13: 40237 | DJ13: 40268 | DK13: 40298 | DL13: 40329 | DM13: 40359 | DN13: 40390 | DO13: 40421 | DP13: 40451 | DQ13: 40482 | DR13: 40512 | DS13: 40543 | DT13: 40574 | DU13: 40602 | DV13: 40633 | DW13: 40663 | DX13: 40694 | DY13: 40724 | DZ13: 40755 | EA13: 40786 | EB13: 40816 | EC13: 40847 | ED13: 40877 | EE13: 40908 | EF13: 40939 | EG13: 40968 | EH13: 40999 | EI13: 41029 | EJ13: 41060 | EK13: 41090 | EL13: 41121 | EM13: 41152 | EN13: 41182 | EO13: 41213 | EP13: 41243 | EQ13: 41274 | ER13: 41305 | ES13: 41333 | ET13: 41364 | EU13: 41394 | EV13: 41425 | EW13: 41455 | EX13: 41486 | EY13: 41517 | EZ13: 41547 | FA13: 41578 | FB13: 41608 | FC13: 41639 | FD13: 41670 | FE13: 41698 | FF13: 41729 | FG13: 41759 | FH13: 41790 | FI13: 41820 | FJ13: 41851 | FK13: 41882 | FL13: 41912 | FM13: 41943 | FN13: 41973 | FO13: 42004 | FP13: 42035 | FQ13: 42063 | FR13: 42094 | FS13: 42124 | FT13: 42155 | FU13: 42185 | FV13: 42216 | FW13: 42247 | FX13: 42277 | FY13: 42308 | FZ13: 42338 | GA13: 42369 | GB13: 42400 | GC13: 42429 | GD13: 42460 | GE13: 42490 | GF13: 42521 | GG13: 42551 | GH13: 42582 | GI13: 42613 | GJ13: 42643 | GK13: 42674 | GL13: 42704 | GM13: 42735 | GN13: 42766 | GO13: 42794 | GP13: 42825 | GQ13: 42855 | GR13: 42886 | GS13: 42916 | GT13: 42947 | GU13: 42978 | GV13: 43008 | GW13: 43039 | GX13: 43069 | GY13: 43100 | GZ13: 43131 | HA13: 43159 | HB13: 43190 | HC13: 43220 | HD13: 43251 | HE13: 43281 | HF13: 43312 | HG13: 43343 | HH13: 43373 | HI13: 43404 | HJ13: 43434 | HK13: 43465 | HL13: 43496 | HM13: 43524 | HN13: 43555 | HO13: 43585 | HP13: 43616 | HQ13: 43646 | HR13: 43677 | HS13: 43708 | HT13: 43738 | HU13: 43769 | HV13: 43799 | HW13: 43830 | HX13: 43861 | HY13: 43890 | HZ13: 43921 | IA13: 43951 | IB13: 43982 | IC13: 44012 | ID13: 44043 | IE13: 44074 | IF13: 44104 | IG13: 44135 | IH13: 44165 | II13: 44196 | IJ13: 44227 | IK13: 44255 | IL13: 44286 | IM13: 44316 | IN13: 44347 | IO13: 44377 | IP13: 44408 | IQ13: 44439 | IR13: 44469 | IS13: 44500 | IT13: 44530 | IU13: 44561 | IV13: 44592 | IW13: 44620 | IX13: 44651 | IY13: 44681 | IZ13: 44712 | JA13: 44742 | JB13: 44773 | JC13: 44804 | JD13: 44834 | JE13: 44865 | JF13: 44895 | JG13: 44926 | JH13: 44957 | JI13: 44985 | JJ13: 45016 | JK13: 45046 | JL13: 45077 | JM13: 45107 | JN13: 45138 | JO13: 45169 | JP13: 45199 | JQ13: 45230 | JR13: 45260 | JS13: 45291 | JT13: 45322 | JU13: 45351 | JV13: 45382 | JW13: 45412 | JX13: 45443 | JY13: 45473 | JZ13: 45504 | KA13: 45535 | KB13: 45565 | KC13: 45596 | KD13: 45626 | KE13: 45657 | KF13: 45688 | KG13: 45716 | KH13: 45747 | KI13: 45777 | KJ13: 45808 | KK13: 45838 | KL13: 45869 | KM13: 45900 | KN13: 45930 | KO13: 45961 | KP13: 45991 | KQ13: 46022 | KR13: 46053 | KS13: 46081 | KT13: 46112 | KU13: 46142 | KV13: 46173 | KW13: 46203 | KX13: 46234 | KY13: 46265 | KZ13: 46295 | LA13: 46326 | LB13: 46356 | LC13: 46387 | LD13: 46418 | LE13: 46446 | LF13: 46477 | LG13: 46507 | LH13: 46538 | LI13: 46568 | LJ13: 46599 | LK13: 46630 | LL13: 46660 | LM13: 46691 | LN13: 46721 | LO13: 46752 | LP13: 46783 | LQ13: 46812 | LR13: 46843 | LS13: 46873 | LT13: 46904 | LU13: 46934 | LV13: 46965 | LW13: 46996 | LX13: 47026 | LY13: 47057 | LZ13: 47087 | MA13: 47118 | MB13: 47149 | MC13: 47177 | MD13: 47208 | ME13: 47238 | MF13: 47269 | MG13: 47299 | MH13: 47330 | MI13: 47361 | MJ13: 47391 | MK13: 47422 | ML13: 47452 | MM13: 47483 | MN13: 47514 | MO13: 47542 | MP13: 47573 | MQ13: 47603 | MR13: 47634 | MS13: 47664 | MT13: 47695 | MU13: 47726 | MV13: 47756 | MW13: 47787 | MX13: 47817 | MY13: 47848 | MZ13: 47879 | NA13: 47907 | NB13: 47938 | NC13: 47968 | ND13: 47999 | NE13: 48029 | NF13: 48060 | NG13: 48091 | NH13: 48121 | NI13: 48152 | NJ13: 48182 | NK13: 48213 | NL13: 48244 | NM13: 48273 | NN13: 48304 | NO13: 48334 | NP13: 48365 | NQ13: 48395 | NR13: 48426 | NS13: 48457 | NT13: 48487 | NU13: 48518 | NV13: 48548 | NW13: 48579 | NX13: 48610 | NY13: 48638 | NZ13: 48669 | OA13: 48699 | OB13: 48730 | OC13: 48760 | OD13: 48791 | OE13: 48822 | OF13: 48852 | OG13: 48883 | OH13: 48913 | OI13: 48944 | OJ13: 48975 | OK13: 49003 | OL13: 49034 | OM13: 49064 | ON13: 49095 | OO13: 49125 | OP13: 49156 | OQ13: 49187 | OR13: 49217 | OS13: 49248 | OT13: 49278 | OU13: 49309 | OV13: 49340 | OW13: 49368 | OX13: 49399 | OY13: 49429 | OZ13: 49460 | PA13: 49490 | PB13: 49521 | PC13: 49552 | PD13: 49582 | PE13: 49613 | PF13: 49643 | PG13: 49674 | PH13: 49705 | PI13: 49734 | PJ13: 49765 | PK13: 49795 | PL13: 49826 | PM13: 49856 | PN13: 49887 | PO13: 49918 | PP13: 49948 | PQ13: 49979 | PR13: 50009 | PS13: 50040 | PT13: 50071 | PU13: 50099 | PV13: 50130 | PW13: 50160 | PX13: 50191 | PY13: 50221 | PZ13: 50252 | QA13: 50283 | QB13: 50313 | QC13: 50344 | QD13: 50374 | QE13: 50405 | QF13: 50436 | QG13: 50464 | QH13: 50495 | QI13: 50525 | QJ13: 50556 | QK13: 50586 | QL13: 50617 | QM13: 50648 | QN13: 50678 | QO13: 50709 | QP13: 50739 | QQ13: 50770 | QR13: 50801 | QS13: 50829 | QT13: 50860 | QU13: 50890 | QV13: 50921 | QW13: 50951 | QX13: 50982 | QY13: 51013 | QZ13: 51043 | RA13: 51074 | RB13: 51104 | RC13: 51135 | RD13: 51166 | RE13: 51195 | RF13: 51226 | RG13: 51256 | RH13: 51287 | RI13: 51317 | RJ13: 51348 | RK13: 51379 | RL13: 51409 | RM13: 51440 | RN13: 51470 | RO13: 51501 | RP13: 51532 | RQ13: 51560 | RR13: 51591 | RS13: 51621 | RT13: 51652 | RU13: 51682 | RV13: 51713 | RW13: 51744 | RX13: 51774 | RY13: 51805 | RZ13: 51835 | SA13: 51866 | SB13: 51897 | SC13: 51925 | SD13: 51956 | SE13: 51986 | SF13: 52017 | SG13: 52047 | SH13: 52078 | SI13: 52109 | SJ13: 52139 | SK13: 52170 | SL13: 52200 | SM13: 52231 | SN13: 52262 | SO13: 52290 | SP13: 52321 | SQ13: 52351 | SR13: 52382 | SS13: 52412 | ST13: 52443 | SU13: 52474 | SV13: 52504 | SW13: 52535 | SX13: 52565 | SY13: 52596 | SZ13: 52627 | TA13: 52656 | TB13: 52687 | TC13: 52717 | TD13: 52748 | TE13: 52778 | TF13: 52809 | TG13: 52840 | TH13: 52870 | TI13: 52901 | TJ13: 52931 | TK13: 52962 | TL13: 52993 | TM13: 53021 | TN13: 53052 | TO13: 53082 | TP13: 53113 | TQ13: 53143 | TR13: 53174 | TS13: 53205 | TT13: 53235 | TU13: 53266 | TV13: 53296 | TW13: 53327 | TX13: 53358 | TY13: 53386 | TZ13: 53417 | UA13: 53447 | UB13: 53478 | UC13: 53508 | UD13: 53539 | UE13: 53570 | UF13: 53600 | UG13: 53631 | UH13: 53661 | UI13: 53692 | UJ13: 53723 | UK13: 53751 | UL13: 53782 | UM13: 53812 | UN13: 53843 | UO13: 53873 | UP13: 53904 | UQ13: 53935 | UR13: 53965 | US13: 53996 | UT13: 54026 | UU13: 54057 | UV13: 54088 | UW13: 54117 | UX13: 54148 | UY13: 54178 | UZ13: 54209 | VA13: 54239 | VB13: 54270 | VC13: 54301 | VD13: 54331 | VE13: 54362 | VF13: 54392 | VG13: 54423 | VH13: 54454 | VI13: 54482 | VJ13: 54513 | VK13: 54543 | VL13: 54574 | VM13: 54604 | VN13: 54635 | VO13: 54666 | VP13: 54696 | VQ13: 54727 | VR13: 54757 | VS13: 54788 | VT13: 54819 | VU13: 54847 | VV13: 54878 | VW13: 54908 | VX13: 54939 | VY13: 54969 | VZ13: 55000 | WA13: 55031 | WB13: 55061 | WC13: 55092 | WD13: 55122 | WE13: 55153 | WF13: 55184 | WG13: 55212 | WH13: 55243 | WI13: 55273 | WJ13: 55304 | WK13: 55334 | WL13: 55365 | WM13: 55396 | WN13: 55426 | WO13: 55457 | WP13: 55487 | WQ13: 55518 | WR13: 55549 | WS13: 55578 | WT13: 55609 | WU13: 55639 | WV13: 55670 | WW13: 55700 | WX13: 55731 | WY13: 55762 | WZ13: 55792 | XA13: 55823 | XB13: 55853 | XC13: 55884 | XD13: 55915 | XE13: 55943 | XF13: 55974 | XG13: 56004 | XH13: 56035 | XI13: 56065 | XJ13: 56096 | XK13: 56127 | XL13: 56157 | XM13: 56188 | XN13: 56218 | XO13: 56249 | XP13: 56280 | XQ13: 56308 | XR13: 56339 | XS13: 56369 | XT13: 56400 | XU13: 56430 | XV13: 56461 | XW13: 56492 | XX13: 56522 | XY13: 56553 | XZ13: 56583 | YA13: 56614 | YB13: 56645 | YC13: 56673 | YD13: 56704 | YE13: 56734 | YF13: 56765 | YG13: 56795 | YH13: 56826 | YI13: 56857 | YJ13: 56887 | YK13: 56918 | YL13: 56948 | YM13: 56979
A15: Cálculo Años
A16: Años Ex Ante | B16: 1 | C16: 13 | D16: 25 | E16: 37 | F16: 49
B17: =HLOOKUP(B16,$C$6:$YM$7,2,FALSE) -> 36891 | C17: =HLOOKUP(C16,$C$6:$YM$7,2,FALSE) -> 37256 | D17: =HLOOKUP(D16,$C$6:$YM$7,2,FALSE) -> 37621 | E17: =HLOOKUP(E16,$C$6:$YM$7,2,FALSE) -> 37986 | F17: =HLOOKUP(F16,$C$6:$YM$7,2,FALSE) -> 38352
A19: Años Ex Post | B19: 1 | C19: 13 | D19: 25 | E19: 37 | F19: 49
B20: =HLOOKUP(B19,$C$12:$YM$13,2,FALSE) -> 36891 | C20: =HLOOKUP(C19,$C$12:$YM$13,2,FALSE) -> 37256 | D20: =HLOOKUP(D19,$C$12:$YM$13,2,FALSE) -> 37621 | E20: =HLOOKUP(E19,$C$12:$YM$13,2,FALSE) -> 37986 | F20: =HLOOKUP(F19,$C$12:$YM$13,2,FALSE) -> 38352

Sheet IPIM y USD
A1: INDEC - Índice de Precios Internos al Por Mayor | D1: NO MODIFICAR NI MANIPULAR DATOS DE ESTA SOLAPA
A2: Fuente de los datos
A3: Hasta dic 2015: https://www.indec.gob.ar/indec/web/Nivel4-Tema-3-5-32. En vínculo "Serie mensual desde 1996 en adelante".
A4: Desde dic 2015: https://www.indec.gob.ar/ftp/cuadros/economia/series_sipm_dic2015.xls
A6: Calendario ex ante | C6: 36861 | D6: 36892 | E6: 36923 | F6: 36951 | G6: 36982 | H6: 37012 | I6: 37043 | J6: 37073 | K6: 37104 | L6: 37135 | M6: 37165 | N6: 37196 | O6: 37226 | P6: 37257 | Q6: 37288 | R6: 37316 | S6: 37347 | T6: 37377 | U6: 37408 | V6: 37438 | W6: 37469 | X6: 37500 | Y6: 37530 | Z6: 37561 | AA6: 37591 | AB6: 37622 | AC6: 37653 | AD6: 37681 | AE6: 37712 | AF6: 37742 | AG6: 37773 | AH6: 37803 | AI6: 37834 | AJ6: 37865 | AK6: 37895 | AL6: 37926 | AM6: 37956 | AN6: 37987 | AO6: 38018 | AP6: 38047 | AQ6: 38078 | AR6: 38108 | AS6: 38139 | AT6: 38169 | AU6: 38200 | AV6: 38231 | AW6: 38261 | AX6: 38292 | AY6: 38322 | AZ6: 38353 | BA6: 38384 | BB6: 38412 | BC6: 38443 | BD6: 38473 | BE6: 38504 | BF6: 38534 | BG6: 38565 | BH6: 38596 | BI6: 38626 | BJ6: 38657 | BK6: 38687 | BL6: 38718 | BM6: 38749 | BN6: 38777 | BO6: 38808 | BP6: 38838 | BQ6: 38869 | BR6: 38899 | BS6: 38930 | BT6: 38961 | BU6: 38991 | BV6: 39022 | BW6: 39052 | BX6: 39083 | BY6: 39114 | BZ6: 39142 | CA6: 39173 | CB6: 39203 | CC6: 39234 | CD6: 39264 | CE6: 39295 | CF6: 39326 | CG6: 39356 | CH6: 39387 | CI6: 39417 | CJ6: 39448 | CK6: 39479 | CL6: 39508 | CM6: 39539 | CN6: 39569 | CO6: 39600 | CP6: 39630 | CQ6: 39661 | CR6: 39692 | CS6: 39722 | CT6: 39753 | CU6: 39783 | CV6: 39814 | CW6: 39845 | CX6: 39873 | CY6: 39904 | CZ6: 39934 | DA6: 39965 | DB6: 39995 | DC6: 40026 | DD6: 40057 | DE6: 40087 | DF6: 40118 | DG6: 40148 | DH6: 40179 | DI6: 40210 | DJ6: 40238 | DK6: 40269 | DL6: 40299 | DM6: 40330 | DN6: 40360 | DO6: 40391 | DP6: 40422 | DQ6: 40452 | DR6: 40483 | DS6: 40513 | DT6: 40544 | DU6: 40575 | DV6: 40603 | DW6: 40634 | DX6: 40664 | DY6: 40695 | DZ6: 40725 | EA6: 40756 | EB6: 40787 | EC6: 40817 | ED6: 40848 | EE6: 40878 | EF6: 40909 | EG6: 40940 | EH6: 40969 | EI6: 41000 | EJ6: 41030 | EK6: 41061 | EL6: 41091 | EM6: 41122 | EN6: 41153 | EO6: 41183 | EP6: 41214 | EQ6: 41244 | ER6: 41275 | ES6: 41306 | ET6: 41334 | EU6: 41365 | EV6: 41395 | EW6: 41426 | EX6: 41456 | EY6: 41487 | EZ6: 41518 | FA6: 41548 | FB6: 41579 | FC6: 41609 | FD6: 41640 | FE6: 41671 | FF6: 41699 | FG6: 41730 | FH6: 41760 | FI6: 41791 | FJ6: 41821 | FK6: 41852 | FL6: 41883 | FM6: 41913 | FN6: 41944 | FO6: 41974 | FP6: 42005 | FQ6: 42036 | FR6: 42064 | FS6: 42095 | FT6: 42125 | FU6: 42156 | FV6: 42186 | FW6: 42217 | FX6: 42248 | FY6: 42278 | FZ6: 42309 | GA6: 42339 | GB6: 42370 | GC6: 42401 | GD6: 42430 | GE6: 42461 | GF6: 42491 | GG6: 42522 | GH6: 42552 | GI6: 42583 | GJ6: 42614 | GK6: 42644 | GL6: 42675 | GM6: 42705 | GN6: 42736 | GO6: 42767 | GP6: 42795 | GQ6: 42826 | GR6: 42856 | GS6: 42887 | GT6: 42917 | GU6: 42948 | GV6: 42979 | GW6: 43009 | GX6: 43040 | GY6: 43070 | GZ6: 43101 | HA6: 43132 | HB6: 43160 | HC6: 43191 | HD6: 43221 | HE6: 43252 | HF6: 43282 | HG6: 43313 | HH6: 43344 | HI6: 43374 | HJ6: 43405 | HK6: 43435 | HL6: 43466 | HM6: 43497 | HN6: 43525 | HO6: 43556 | HP6: 43586 | HQ6: 43617 | HR6: 43647 | HS6: 43678 | HT6: 43709 | HU6: 43739 | HV6: 43770 | HW6: 43800 | HX6: 43831 | HY6: 43862 | HZ6: 43891 | IA6: 43922 | IB6: 43952 | IC6: 43983 | ID6: 44013 | IE6: 44044 | IF6: 44075 | IG6: 44105 | IH6: 44136 | II6: 44166 | IJ6: 44197 | IK6: 44228 | IL6: 44256 | IM6: 44287 | IN6: 44317 | IO6: 44348 | IP6: 44378 | IQ6: 44409 | IR6: 44440 | IS6: 44470 | IT6: 44501 | IU6: 44531 | IV6: 44562 | IW6: 44593 | IX6: 44621 | IY6: 44652 | IZ6: 44682 | JA6: 44713 | JB6: 44743 | JC6: 44774 | JD6: 44805 | JE6: 44835 | JF6: 44866 | JG6: 44896 | JH6: 44927 | JI6: 44958 | JJ6: 44986 | JK6: 45017 | JL6: 45047 | JM6: 45078 | JN6: 45108 | JO6: 45139 | JP6: 45170 | JQ6: 45200 | JR6: 45231 | JS6: 45261 | JT6: 45292 | JU6: 45323 | JV6: 45352 | JW6: 45383 | JX6: 45413 | JY6: 45444 | JZ6: 45474 | KA6: 45505 | KB6: 45536 | KC6: 45566 | KD6: 45597 | KE6: 45627 | KF6: 45658 | KG6: 45689 | KH6: 45717 | KI6: 45748 | KJ6: 45778 | KK6: 45809 | KL6: 45839 | KM6: 45870 | KN6: 45901 | KO6: 45931 | KP6: 45962 | KQ6: 45992 | KR6: 46023 | KS6: 46054 | KT6: 46082 | KU6: 46113 | KV6: 46143 | KW6: 46174 | KX6: 46204 | KY6: 46235 | KZ6: 46266 | LA6: 46296 | LB6: 46327 | LC6: 46357 | LD6: 46388 | LE6: 46419 | LF6: 46447 | LG6: 46478 | LH6: 46508 | LI6: 46539 | LJ6: 46569 | LK6: 46600 | LL6: 46631 | LM6: 46661 | LN6: 46692 | LO6: 46722 | LP6: 46753 | LQ6: 46784 | LR6: 46813 | LS6: 46844 | LT6: 46874 | LU6: 46905 | LV6: 46935 | LW6: 46966 | LX6: 46997 | LY6: 47027 | LZ6: 47058 | MA6: 47088 | MB6: 47119 | MC6: 47150 | MD6: 47178 | ME6: 47209 | MF6: 47239 | MG6: 47270 | MH6: 47300 | MI6: 47331 | MJ6: 47362 | MK6: 47392 | ML6: 47423 | MM6: 47453 | MN6: 47484 | MO6: 47515 | MP6: 47543 | MQ6: 47574 | MR6: 47604 | MS6: 47635 | MT6: 47665 | MU6: 47696 | MV6: 47727 | MW6: 47757 | MX6: 47788 | MY6: 47818 | MZ6: 47849 | NA6: 47880 | NB6: 47908 | NC6: 47939 | ND6: 47969 | NE6: 48000 | NF6: 48030 | NG6: 48061 | NH6: 48092 | NI6: 48122 | NJ6: 48153 | NK6: 48183 | NL6: 48214 | NM6: 48245 | NN6: 48274 | NO6: 48305 | NP6: 48335 | NQ6: 48366 | NR6: 48396 | NS6: 48427 | NT6: 48458 | NU6: 48488 | NV6: 48519 | NW6: 48549 | NX6: 48580 | NY6: 48611 | NZ6: 48639 | OA6: 48670 | OB6: 48700 | OC6: 48731 | OD6: 48761 | OE6: 48792 | OF6: 48823 | OG6: 48853 | OH6: 48884 | OI6: 48914
A7: Calendario ex post | C7: 36891 | D7: 36922 | E7: 36950 | F7: 36981 | G7: 37011 | H7: 37042 | I7: 37072 | J7: 37103 | K7: 37134 | L7: 37164 | M7: 37195 | N7: 37225 | O7: 37256 | P7: 37287 | Q7: 37315 | R7: 37346 | S7: 37376 | T7: 37407 | U7: 37437 | V7: 37468 | W7: 37499 | X7: 37529 | Y7: 37560 | Z7: 37590 | AA7: 37621 | AB7: 37652 | AC7: 37680 | AD7: 37711 | AE7: 37741 | AF7: 37772 | AG7: 37802 | AH7: 37833 | AI7: 37864 | AJ7: 37894 | AK7: 37925 | AL7: 37955 | AM7: 37986 | AN7: 38017 | AO7: 38046 | AP7: 38077 | AQ7: 38107 | AR7: 38138 | AS7: 38168 | AT7: 38199 | AU7: 38230 | AV7: 38260 | AW7: 38291 | AX7: 38321 | AY7: 38352 | AZ7: 38383 | BA7: 38411 | BB7: 38442 | BC7: 38472 | BD7: 38503 | BE7: 38533 | BF7: 38564 | BG7: 38595 | BH7: 38625 | BI7: 38656 | BJ7: 38686 | BK7: 38717 | BL7: 38748 | BM7: 38776 | BN7: 38807 | BO7: 38837 | BP7: 38868 | BQ7: 38898 | BR7: 38929 | BS7: 38960 | BT7: 38990 | BU7: 39021 | BV7: 39051 | BW7: 39082 | BX7: 39113 | BY7: 39141 | BZ7: 39172 | CA7: 39202 | CB7: 39233 | CC7: 39263 | CD7: 39294 | CE7: 39325 | CF7: 39355 | CG7: 39386 | CH7: 39416 | CI7: 39447 | CJ7: 39478 | CK7: 39507 | CL7: 39538 | CM7: 39568 | CN7: 39599 | CO7: 39629 | CP7: 39660 | CQ7: 39691 | CR7: 39721 | CS7: 39752 | CT7: 39782 | CU7: 39813 | CV7: 39844 | CW7: 39872 | CX7: 39903 | CY7: 39933 | CZ7: 39964 | DA7: 39994 | DB7: 40025 | DC7: 40056 | DD7: 40086 | DE7: 40117 | DF7: 40147 | DG7: 40178 | DH7: 40209 | DI7: 40237 | DJ7: 40268 | DK7: 40298 | DL7: 40329 | DM7: 40359 | DN7: 40390 | DO7: 40421 | DP7: 40451 | DQ7: 40482 | DR7: 40512 | DS7: 40543 | DT7: 40574 | DU7: 40602 | DV7: 40633 | DW7: 40663 | DX7: 40694 | DY7: 40724 | DZ7: 40755 | EA7: 40786 | EB7: 40816 | EC7: 40847 | ED7: 40877 | EE7: 40908 | EF7: 40939 | EG7: 40968 | EH7: 40999 | EI7: 41029 | EJ7: 41060 | EK7: 41090 | EL7: 41121 | EM7: 41152 | EN7: 41182 | EO7: 41213 | EP7: 41243 | EQ7: 41274 | ER7: 41305 | ES7: 41333 | ET7: 41364 | EU7: 41394 | EV7: 41425 | EW7: 41455 | EX7: 41486 | EY7: 41517 | EZ7: 41547 | FA7: 41578 | FB7: 41608 | FC7: 41639 | FD7: 41670 | FE7: 41698 | FF7: 41729 | FG7: 41759 | FH7: 41790 | FI7: 41820 | FJ7: 41851 | FK7: 41882 | FL7: 41912 | FM7: 41943 | FN7: 41973 | FO7: 42004 | FP7: 42035 | FQ7: 42063 | FR7: 42094 | FS7: 42124 | FT7: 42155 | FU7: 42185 | FV7: 42216 | FW7: 42247 | FX7: 42277 | FY7: 42308 | FZ7: 42338 | GA7: 42369 | GB7: 42400 | GC7: 42429 | GD7: 42460 | GE7: 42490 | GF7: 42521 | GG7: 42551 | GH7: 42582 | GI7: 42613 | GJ7: 42643 | GK7: 42674 | GL7: 42704 | GM7: 42735 | GN7: 42766 | GO7: 42794 | GP7: 42825 | GQ7: 42855 | GR7: 42886 | GS7: 42916 | GT7: 42947 | GU7: 42978 | GV7: 43008 | GW7: 43039 | GX7: 43069 | GY7: 43100 | GZ7: 43131 | HA7: 43159 | HB7: 43190 | HC7: 43220 | HD7: 43251 | HE7: 43281 | HF7: 43312 | HG7: 43343 | HH7: 43373 | HI7: 43404 | HJ7: 43434 | HK7: 43465 | HL7: 43496 | HM7: 43524 | HN7: 43555 | HO7: 43585 | HP7: 43616 | HQ7: 43646 | HR7: 43677 | HS7: 43708 | HT7: 43738 | HU7: 43769 | HV7: 43799 | HW7: 43830 | HX7: 43861 | HY7: 43890 | HZ7: 43921 | IA7: 43951 | IB7: 43982 | IC7: 44012 | ID7: 44043 | IE7: 44074 | IF7: 44104 | IG7: 44135 | IH7: 44165 | II7: 44196 | IJ7: 44227 | IK7: 44255 | IL7: 44286 | IM7: 44316 | IN7: 44347 | IO7: 44377 | IP7: 44408 | IQ7: 44439 | IR7: 44469 | IS7: 44500 | IT7: 44530 | IU7: 44561 | IV7: 44592 | IW7: 44620 | IX7: 44651 | IY7: 44681 | IZ7: 44712 | JA7: 44742 | JB7: 44773 | JC7: 44804 | JD7: 44834 | JE7: 44865 | JF7: 44895 | JG7: 44926 | JH7: 44957 | JI7: 44985 | JJ7: 45016 | JK7: 45046 | JL7: 45077 | JM7: 45107 | JN7: 45138 | JO7: 45169 | JP7: 45199 | JQ7: 45230 | JR7: 45260 | JS7: 45291 | JT7: 45322 | JU7: 45351 | JV7: 45382 | JW7: 45412 | JX7: 45443 | JY7: 45473 | JZ7: 45504 | KA7: 45535 | KB7: 45565 | KC7: 45596 | KD7: 45626 | KE7: 45657 | KF7: 45688 | KG7: 45716 | KH7: 45747 | KI7: 45777 | KJ7: 45808 | KK7: 45838 | KL7: 45869 | KM7: 45900 | KN7: 45930 | KO7: 45961 | KP7: 45991 | KQ7: 46022 | KR7: 46053 | KS7: 46081 | KT7: 46112 | KU7: 46142 | KV7: 46173 | KW7: 46203 | KX7: 46234 | KY7: 46265 | KZ7: 46295 | LA7: 46326 | LB7: 46356 | LC7: 46387 | LD7: 46418 | LE7: 46446 | LF7: 46477 | LG7: 46507 | LH7: 46538 | LI7: 46568 | LJ7: 46599 | LK7: 46630 | LL7: 46660 | LM7: 46691 | LN7: 46721 | LO7: 46752 | LP7: 46783 | LQ7: 46812 | LR7: 46843 | LS7: 46873 | LT7: 46904 | LU7: 46934 | LV7: 46965 | LW7: 46996 | LX7: 47026 | LY7: 47057 | LZ7: 47087 | MA7: 47118 | MB7: 47149 | MC7: 47177 | MD7: 47208 | ME7: 47238 | MF7: 47269 | MG7: 47299 | MH7: 47330 | MI7: 47361 | MJ7: 47391 | MK7: 47422 | ML7: 47452 | MM7: 47483 | MN7: 47514 | MO7: 47542 | MP7: 47573 | MQ7: 47603 | MR7: 47634 | MS7: 47664 | MT7: 47695 | MU7: 47726 | MV7: 47756 | MW7: 47787 | MX7: 47817 | MY7: 47848 | MZ7: 47879 | NA7: 47907 | NB7: 47938 | NC7: 47968 | ND7: 47999 | NE7: 48029 | NF7: 48060 | NG7: 48091 | NH7: 48121 | NI7: 48152 | NJ7: 48182 | NK7: 48213 | NL7: 48244 | NM7: 48273 | NN7: 48304 | NO7: 48334 | NP7: 48365 | NQ7: 48395 | NR7: 48426 | NS7: 48457 | NT7: 48487 | NU7: 48518 | NV7: 48548 | NW7: 48579 | NX7: 48610 | NY7: 48638 | NZ7: 48669 | OA7: 48699 | OB7: 48730 | OC7: 48760 | OD7: 48791 | OE7: 48822 | OF7: 48852 | OG7: 48883 | OH7: 48913 | OI7: 48944
A8: IPIM | B8: Nivel general | D8: 100 | E8: =+D8*(1+E9) -> 100.11335 | F8: =+E8*(1+F9) -> 99.452158 | G8: =+F8*(1+G9) -> 99.263247 | H8: =+G8*(1+H9) -> 99.338812 | I8: =+H8*(1+I9) -> 98.894871 | J8: =+I8*(1+J9) -> 98.545386 | K8: =+J8*(1+K9) -> 98.063663 | L8: =+K8*(1+L9) -> 97.638613 | ... KR8: =+KQ8*(1+KR9) -> 126960.32
