Workbook

Sheet 2.2.Brecha Efectiva x UdM
A1: Cuadro 2.2.1. Brecha Efectiva por UdM, 2024 - 2033, en millones de pesos, (sin ajustes)
A2: JURISDICCIÓN | B2: SECTOR | C2: Unidad de Medida (UdM) | D2: Brecha x UdM (millones $) META 2053 | E2: Plazo (Años) META 2053 | F2: Brecha x UdM (millones $) META 2033 | G2: (%) de la Brecha cubierto en 2033 | H2: 2024 | I2: 2025 | J2: 2026 | K2: 2027 | L2: 2028 | M2: 2029 | N2: 2030 | O2: 2031 | P2: 2032 | Q2: 2033 | R2: 2034 | S2: 2035 | T2: 2036 | U2: 2037 | V2: 2038 | W2: 2039 | X2: 2040 | Y2: 2041 | Z2: 2042 | AA2: 2043 | AB2: 2044 | AC2: 2045 | AD2: 2046 | AE2: 2047 | AF2: 2048 | AG2: 2049 | AH2: 2050 | AI2: 2051 | AJ2: 2052 | AK2: 2053
A3: Nombre Jurisdicción | B3: Nombre Sector | C3: Nombre UdM 1 | D3: =SUM(H3:AK3) -> 17996390400 | E3: =COUNTIF(H3:AK3,">0") -> 10 | F3: =SUM(H3:Q3) -> 17996390400 | G3: =IFERROR(F3/D3,0) -> 1 | H3: 3944448000 | I3: 3944448000 | J3: 2428928000 | K3: 1910886400 | L3: 1000000000 | M3: 1000000000 | N3: 1000000000 | O3: 922560000 | P3: 922560000 | Q3: 922560000
A4: Nombre Jurisdicción | B4: Nombre Sector | C4: Nombre UdM 2 | D4: =SUM(H4:AK4) -> 1.009931e+10 | E4: =COUNTIF(H4:AK4,">0") -> 3 | F4: =SUM(H4:Q4) -> 1.009931e+10 | G4: =IFERROR(F4/D4,0) -> 1 | H4: 2.7610423e+09 | I4: 2.9365119e+09 | J4: 4.4017558e+09
A5: Nombre Jurisdicción | B5: Nombre Sector | C5: Nombre UdM 3 | D5: =SUM(H5:AK5) -> 7.5090704e+09 | E5: =COUNTIF(H5:AK5,">0") -> 4 | F5: =SUM(H5:Q5) -> 7.5090704e+09 | G5: =IFERROR(F5/D5,0) -> 1 | H5: 9.0875594e+08 | I5: 6.1241118e+09 | J5: 3.0868853e+08 | K5: 1.6751418e+08
A6: Nombre Jurisdicción | B6: Nombre Sector | D6: =SUM(H6:AK6) -> 0 | E6: =COUNTIF(H6:AK6,">0") -> 0 | F6: =SUM(H6:Q6) -> 0 | G6: =IFERROR(F6/D6,0) -> 0
A7: Nombre Jurisdicción | B7: Nombre Sector | D7: =SUM(H7:AK7) -> 0 | E7: =COUNTIF(H7:AK7,">0") -> 0 | F7: =SUM(H7:Q7) -> 0 | G7: =IFERROR(F7/D7,0) -> 0
A8: Nombre Jurisdicción | B8: Nombre Sector | D8: =SUM(H8:AK8) -> 0 | E8: =COUNTIF(H8:AK8,">0") -> 0 | F8: =SUM(H8:Q8) -> 0 | G8: =IFERROR(F8/D8,0) -> 0
A9: TOTAL | D9: =SUM(D3:D8) -> 3.5604771e+10 | F9: =SUM(F3:F8) -> 3.5604771e+10 | G9: =IFERROR(F9/D9,0) -> 1 | H9: =SUM(H3:H8) -> 7.6142463e+09 | I9: =SUM(I3:I8) -> 1.3005072e+10 | J9: =SUM(J3:J8) -> 7.1393723e+09 | K9: =SUM(K3:K8) -> 2.0784006e+09 | L9: =SUM(L3:L8) -> 1000000000 | M9: =SUM(M3:M8) -> 1000000000 | N9: =SUM(N3:N8) -> 1000000000 | O9: =SUM(O3:O8) -> 922560000 | ... AK9: =SUM(AK3:AK8) -> 0
A11: INSTRUCTIVO
A13: Por favor, completar únicamente la columna C (UdM) y las columnas a partir de H (años de la curva de inversión) que correspondan según la estimación de la jurisdicción. (Ejemplo en Rojo)
A14: Los montos deben ser completados en pesos, ingresando la cifra completa (no en millones). El Excel mostrará, automáticamente, el monto en formato millones.
A15: Por favor, ordenar las UdM de manera que la de mayor monto total quede en primer lugar, y continuar de manera descendente.
A16: Aclaración: Columnas ocultas D y E hacen referencia a casos excepcionales en los que la curva de inversión se extienda más allá de 2033.
A18: AJUSTE DE LA BRECHA EFECTIVA EN FUNCIÓN DEL CRECIMIENTO ESTIMADO DE LA POBLACIÓN (La jurisdicción que lo considere conveniente puede sustituir esta variable de actualización por otra que le resulte más apropiada)
A19: Cuadro 2.2.2 Variable de Actualización e Índice de Actualización - Ejemplo Preestablecido: Evolución de la Población (Actualizar fila 21 cuando esté disponible la proyección poblacional según el censo 2022) | Y19: Estimado | Z19: =(((X21/H21)^(1/17))-1)*100 -> 0.67590777 | AA19: =(((Z21/H21)^(1/19))-1)*100 -> 0.67590777 | AK19: =(((AK21/H21)^(1/30))-1)*100 -> 0.67590777
A20: POBLACIÓN | H20: 2024 | I20: 2025 | J20: 2026 | K20: 2027 | L20: 2028 | M20: 2029 | N20: 2030 | O20: 2031 | P20: 2032 | Q20: 2033 | R20: 2034 | S20: 2035 | T20: 2036 | U20: 2037 | V20: 2038 | W20: 2039 | X20: 2040 | Y20: 2041 | Z20: 2041 | AA20: 2042 | AB20: 2043 | AC20: 2044 | AD20: 2045 | AE20: 2046 | AF20: 2047 | AG20: 2048 | AH20: 2049 | AI20: 2050 | AJ20: 2051 | AK20: 2052
A21: TOTAL (en millones) | H21: 47067641 | I21: 47473760 | J21: 47873268 | K21: 48266524 | L21: 48653385 | M21: 49033678 | N21: 49407265 | O21: 49774276 | P21: 50134861 | Q21: 50488930 | R21: 50836373 | S21: 51177087 | T21: 51511042 | U21: 51838245 | V21: 52158610 | W21: 52472054 | X21: 52778477 | Y21: =X21*(1+(($Z$19)/100)) -> 53135211 | Z21: =Y21*(1+(($Z$19)/100)) -> 53494356 | AA21: =Z21*(1+(($Z$19)/100)) -> 53855928 | AB21: =AA21*(1+(($Z$19)/100)) -> 54219945 | AC21: =AB21*(1+(($Z$19)/100)) -> 54586422 | AD21: =AC21*(1+(($Z$19)/100)) -> 54955375 | AE21: =AD21*(1+(($Z$19)/100)) -> 55326823 | AF21: =AE21*(1+(($Z$19)/100)) -> 55700781 | ... AK21: =AJ21*(1+(($Z$19)/100)) -> 57608830
A22: Indice de Actualización | H22: =(H21/$H$21)*100 -> 100 | I22: =(I21/$H$21)*100 -> 100.86284 | J22: =(J21/$H$21)*100 -> 101.71164 | K22: =(K21/$H$21)*100 -> 102.54715 | L22: =(L21/$H$21)*100 -> 103.36907 | M22: =(M21/$H$21)*100 -> 104.17705 | N22: =(N21/$H$21)*100 -> 104.97077 | O22: =(O21/$H$21)*100 -> 105.75052 | ... AK22: =(AK21/$H$21)*100 -> 122.39583
A24: Cuadro 2.2.3 Brecha Efectiva por UdM, 2024 - 2033, en millones de pesos, ajustada por el índice de actualización
A25: JURISDICCIÓN | B25: SECTOR | C25: Unidad de Medida (UdM) | D25: Brecha x UdM (millones $) META 2053 | E25: Plazo (Años) META 2053 | F25: Brecha x UdM (millones $) META 2033 | G25: (%) de la Brecha cubierto en 2033 | H25: 2024 | I25: 2025 | J25: 2026 | K25: 2027 | L25: 2028 | M25: 2029 | N25: 2030 | O25: 2031 | P25: 2032 | Q25: 2033 | R25: 2034 | S25: 2035 | T25: 2036 | U25: 2037 | V25: 2038 | W25: 2039 | X25: 2040 | Y25: 2041 | Z25: 2042 | AA25: 2043 | AB25: 2044 | AC25: 2045 | AD25: 2046 | AE25: 2047 | AF25: 2048 | AG25: 2049 | AH25: 2050 | AI25: 2051 | AJ25: 2052 | AK25: 2053
A26: =A3 -> Nombre Jurisdicción | B26: =B3 -> Nombre Sector | C26: =C3 -> Nombre UdM 1 | D26: =SUM(H26:AK26) -> 1.8426073e+10 | E26: =COUNTIF(H26:AK26,">0") -> 10 | F26: =SUM(H26:Q26) -> 1.8426073e+10 | G26: =IFERROR(F26/D26,0) -> 1 | H26: =(H3*H$22)/100 -> 3944448000 | I26: =(I3*I$22)/100 -> 3.9784823e+09 | J26: =(J3*J$22)/100 -> 2.4705024e+09 | K26: =(K3*K$22)/100 -> 1.9595595e+09 | L26: =(L3*L$22)/100 -> 1.0336907e+09 | M26: =(M3*M$22)/100 -> 1.0417705e+09 | N26: =(N3*N$22)/100 -> 1.0497077e+09 | O26: =(O3*O$22)/100 -> 9.7561201e+08 | ... AK26: =(AK3*AK$22)/100 -> 0
A27: =A4 -> Nombre Jurisdicción | B27: =B4 -> Nombre Sector | C27: =C4 -> Nombre UdM 2 | D27: =SUM(H27:AK27) -> 1.0199989e+10 | E27: =COUNTIF(H27:AK27,">0") -> 3 | F27: =SUM(H27:Q27) -> 1.0199989e+10 | G27: =IFERROR(F27/D27,0) -> 1 | H27: =(H4*H$22)/100 -> 2.7610423e+09 | I27: =(I4*I$22)/100 -> 2.9618493e+09 | J27: =(J4*J$22)/100 -> 4.4770978e+09 | K27: =(K4*K$22)/100 -> 0 | L27: =(L4*L$22)/100 -> 0 | M27: =(M4*M$22)/100 -> 0 | N27: =(N4*N$22)/100 -> 0 | O27: =(O4*O$22)/100 -> 0 | ... AK27: =(AK4*AK$22)/100 -> 0
A28: =A5 -> Nombre Jurisdicción | B28: =B5 -> Nombre Sector | C28: =C5 -> Nombre UdM 3 | D28: =SUM(H28:AK28) -> 7.5714622e+09 | E28: =COUNTIF(H28:AK28,">0") -> 4 | F28: =SUM(H28:Q28) -> 7.5714622e+09 | G28: =IFERROR(F28/D28,0) -> 1 | H28: =(H5*H$22)/100 -> 9.0875594e+08 | I28: =(I5*I$22)/100 -> 6.1769531e+09 | J28: =(J5*J$22)/100 -> 3.1397216e+08 | K28: =(K5*K$22)/100 -> 1.7178102e+08 | L28: =(L5*L$22)/100 -> 0 | M28: =(M5*M$22)/100 -> 0 | N28: =(N5*N$22)/100 -> 0 | O28: =(O5*O$22)/100 -> 0 | ... AK28: =(AK5*AK$22)/100 -> 0
A29: =A6 -> Nombre Jurisdicción | B29: =B6 -> Nombre Sector | C29: =C6 -> 0 | D29: =SUM(H29:AK29) -> 0 | E29: =COUNTIF(H29:AK29,">0") -> 0 | F29: =SUM(H29:Q29) -> 0 | G29: =IFERROR(F29/D29,0) -> 0 | H29: =(H6*H$22)/100 -> 0 | I29: =(I6*I$22)/100 -> 0 | J29: =(J6*J$22)/100 -> 0 | K29: =(K6*K$22)/100 -> 0 | L29: =(L6*L$22)/100 -> 0 | M29: =(M6*M$22)/100 -> 0 | N29: =(N6*N$22)/100 -> 0 | O29: =(O6*O$22)/100 -> 0 | ... AK29: =(AK6*AK$22)/100 -> 0
A30: =A7 -> Nombre Jurisdicción | B30: =B7 -> Nombre Sector | C30: =C7 -> 0 | D30: =SUM(H30:AK30) -> 0 | E30: =COUNTIF(H30:AK30,">0") -> 0 | F30: =SUM(H30:Q30) -> 0 | G30: =IFERROR(F30/D30,0) -> 0 | H30: =(H7*H$22)/100 -> 0 | I30: =(I7*I$22)/100 -> 0 | J30: =(J7*J$22)/100 -> 0 | K30: =(K7*K$22)/100 -> 0 | L30: =(L7*L$22)/100 -> 0 | M30: =(M7*M$22)/100 -> 0 | N30: =(N7*N$22)/100 -> 0 | O30: =(O7*O$22)/100 -> 0 | ... AK30: =(AK7*AK$22)/100 -> 0
A31: =A8 -> Nombre Jurisdicción | B31: =B8 -> Nombre Sector | C31: =C8 -> 0 | D31: =SUM(H31:AK31) -> 0 | E31: =COUNTIF(H31:AK31,">0") -> 0 | F31: =SUM(H31:Q31) -> 0 | G31: =IFERROR(F31/D31,0) -> 0 | H31: =(H8*H$22)/100 -> 0 | I31: =(I8*I$22)/100 -> 0 | J31: =(J8*J$22)/100 -> 0 | K31: =(K8*K$22)/100 -> 0 | L31: =(L8*L$22)/100 -> 0 | M31: =(M8*M$22)/100 -> 0 | N31: =(N8*N$22)/100 -> 0 | O31: =(O8*O$22)/100 -> 0 | ... AK31: =(AK8*AK$22)/100 -> 0
A32: TOTAL | D32: =SUM(D26:D28) -> 3.6197524e+10 | F32: =SUM(F26:F28) -> 3.6197524e+10 | G32: =IFERROR(F32/D32,0) -> 1 | H32: =SUM(H26:H28) -> 7.6142463e+09 | I32: =SUM(I26:I28) -> 1.3117285e+10 | J32: =SUM(J26:J28) -> 7.2615724e+09 | K32: =SUM(K26:K28) -> 2.1313405e+09 | L32: =SUM(L26:L28) -> 1.0336907e+09 | M32: =SUM(M26:M28) -> 1.0417705e+09 | N32: =SUM(N26:N28) -> 1.0497077e+09 | O32: =SUM(O26:O28) -> 9.7561201e+08 | ... AK32: =SUM(AK26:AK28) -> 0
A33: Nota: Debe tenerse en cuenta que, implícitamente, el ajuste de este valor en función del crecimiento de la población supone, como contracara, una variación en las metas físicas de igual proporción.
A35: COSTO DE REPOSICIÓN EN LAS UDM DURANTE EL AVANCE DE LA BRECHA EFECTIVA
A36: Cuadro 2.2.4. Inversiones de Reposición de las UdMs durante el Avance de la Brecha Efectiva por UdM, 2024 - 2033, en millones de pesos, (sin ajustes)
A37: JURISDICCIÓN | B37: SECTOR | C37: Unidad de Medida (UdM) | H37: 2024 | I37: 2025 | J37: 2026 | K37: 2027 | L37: 2028 | M37: 2029 | N37: 2030 | O37: 2031 | P37: 2032 | Q37: 2033 | R37: 2034 | S37: 2035 | T37: 2036 | U37: 2037 | V37: 2038 | W37: 2039 | X37: 2040 | Y37: 2041 | Z37: 2042 | AA37: 2043 | AB37: 2044 | AC37: 2045 | AD37: 2046 | AE37: 2047 | AF37: 2048 | AG37: 2049 | AH37: 2050 | AI37: 2051 | AJ37: 2052 | AK37: 2053
A38: =A3 -> Nombre Jurisdicción | B38: =B3 -> Nombre Sector | C38: =C3 -> Nombre UdM 1 | H38: 394444800 | I38: 394444800 | J38: 242892800 | K38: 191088640 | L38: 100000000 | M38: 100000000 | N38: 100000000 | O38: 92256000 | P38: 92256000 | Q38: 92256000 | R38: =R3*0.1 -> 0 | S38: =S3*0.1 -> 0 | T38: =T3*0.1 -> 0 | U38: =U3*0.1 -> 0 | V38: =V3*0.1 -> 0 | W38: =W3*0.1 -> 0 | X38: =X3*0.1 -> 0 | Y38: =Y3*0.1 -> 0 | ... AK38: =AK3*0.1 -> 0
A39: =A4 -> Nombre Jurisdicción | B39: =B4 -> Nombre Sector | C39: =C4 -> Nombre UdM 2 | H39: 2.7610423e+08 | I39: 2.9365119e+08 | J39: 4.4017558e+08 | K39: 0 | L39: 0 | M39: 0 | N39: 0 | O39: 0 | P39: 0 | Q39: 0 | R39: =R4*0.1 -> 0 | S39: =S4*0.1 -> 0 | T39: =T4*0.1 -> 0 | U39: =U4*0.1 -> 0 | V39: =V4*0.1 -> 0 | W39: =W4*0.1 -> 0 | X39: =X4*0.1 -> 0 | Y39: =Y4*0.1 -> 0 | ... AK39: =AK4*0.1 -> 0
A40: =A5 -> Nombre Jurisdicción | B40: =B5 -> Nombre Sector | C40: =C5 -> Nombre UdM 3 | H40: 90875594 | I40: 6.1241118e+08 | J40: 30868853 | K40: 16751418 | L40: 0 | M40: 0 | N40: 0 | O40: 0 | P40: 0 | Q40: 0 | R40: =R5*0.1 -> 0 | S40: =S5*0.1 -> 0 | T40: =T5*0.1 -> 0 | U40: =U5*0.1 -> 0 | V40: =V5*0.1 -> 0 | W40: =W5*0.1 -> 0 | X40: =X5*0.1 -> 0 | Y40: =Y5*0.1 -> 0 | ... AK40: =AK5*0.1 -> 0
A41: =A6 -> Nombre Jurisdicción | B41: =B6 -> Nombre Sector | C41: =C6 -> 0 | H41: =H6*0.1 -> 0 | I41: =I6*0.1 -> 0 | J41: =J6*0.1 -> 0 | K41: =K6*0.1 -> 0 | L41: =L6*0.1 -> 0 | M41: =M6*0.1 -> 0 | N41: =N6*0.1 -> 0 | O41: =O6*0.1 -> 0 | ... AK41: =AK6*0.1 -> 0
A42: =A7 -> Nombre Jurisdicción | B42: =B7 -> Nombre Sector | C42: =C7 -> 0 | H42: =H7*0.1 -> 0 | I42: =I7*0.1 -> 0 | J42: =J7*0.1 -> 0 | K42: =K7*0.1 -> 0 | L42: =L7*0.1 -> 0 | M42: =M7*0.1 -> 0 | N42: =N7*0.1 -> 0 | O42: =O7*0.1 -> 0 | ... AK42: =AK7*0.1 -> 0
A43: =A8 -> Nombre Jurisdicción | B43: =B8 -> Nombre Sector | C43: =C8 -> 0 | H43: =H8*0.1 -> 0 | I43: =I8*0.1 -> 0 | J43: =J8*0.1 -> 0 | K43: =K8*0.1 -> 0 | L43: =L8*0.1 -> 0 | M43: =M8*0.1 -> 0 | N43: =N8*0.1 -> 0 | O43: =O8*0.1 -> 0 | ... AK43: =AK8*0.1 -> 0
A44: TOTAL | H44: =SUM(H38:H40) -> 7.6142463e+08 | I44: =SUM(I38:I40) -> 1.3005072e+09 | J44: =SUM(J38:J40) -> 7.1393723e+08 | K44: =SUM(K38:K40) -> 2.0784006e+08 | L44: =SUM(L38:L40) -> 100000000 | M44: =SUM(M38:M40) -> 100000000 | N44: =SUM(N38:N40) -> 100000000 | O44: =SUM(O38:O40) -> 92256000 | ... AK44: =SUM(AK38:AK40) -> 0
A46: INSTRUCTIVO
...

Sheet 2.3.Brecha x Provincia
A1: Cuadro 2.3.1 Brecha por UdM, por Provincia, 2024 - 2033, en millones de pesos, (sin ajustes)
A2: Jurisdicción | B2: ='2.2.Brecha Efectiva x UdM'!A3 -> Nombre Jurisdicción
A3: Unidad de Medida | B3: % | C3: ='2.2.Brecha Efectiva x UdM'!C3 -> Nombre UdM 1 | D3: % | E3: ='2.2.Brecha Efectiva x UdM'!C4 -> Nombre UdM 2 | F3: % | G3: ='2.2.Brecha Efectiva x UdM'!C5 -> Nombre UdM 3 | H3: % | I3: ='2.2.Brecha Efectiva x UdM'!C6 -> 0 | J3: % | K3: ='2.2.Brecha Efectiva x UdM'!C7 -> 0 | L3: % | M3: ='2.2.Brecha Efectiva x UdM'!C8 -> 0 | N3: % | O3: TOTAL
A4: Buenos Aires | B4: =IFERROR(C4/C$28,0) -> 0.081790167 | C4: 1.4719278e+09 | D4: =IFERROR(E4/E$28,0) -> 0.034950626 | E4: 3.529772e+08 | F4: =IFERROR(G4/G$28,0) -> 0.79999608 | G4: 6.0072269e+09 | H4: =IFERROR(I4/I$28,0) -> 0 | I4: 0 | J4: =IFERROR(K4/K$28,0) -> 0 | K4: 0 | L4: =IFERROR(M4/M$28,0) -> 0 | M4: 0 | N4: =IFERROR(O4/O$28,0) -> 0.21997422 | O4: =SUM(C4,E4,G4,I4,K4,M4) -> 7.8321319e+09
A5: CABA | B5: =IFERROR(C5/C$28,0) -> 5.3184577e-05 | C5: 957130.4 | D5: =IFERROR(E5/E$28,0) -> 0.0032654904 | E5: 32979200 | F5: =IFERROR(G5/G$28,0) -> 0.02518396 | G5: 1.8910813e+08 | H5: =IFERROR(I5/I$28,0) -> 0 | I5: 0 | J5: =IFERROR(K5/K$28,0) -> 0 | K5: 0 | L5: =IFERROR(M5/M$28,0) -> 0 | M5: 0 | N5: =IFERROR(O5/O$28,0) -> 0.0062644542 | O5: =SUM(C5,E5,G5,I5,K5,M5) -> 2.2304446e+08
A6: Catamarca | B6: =IFERROR(C6/C$28,0) -> 0.020669489 | C6: 3.7197619e+08 | D6: =IFERROR(E6/E$28,0) -> 0.0055612125 | E6: 56164408 | F6: =IFERROR(G6/G$28,0) -> 0 | G6: 0 | H6: =IFERROR(I6/I$28,0) -> 0 | I6: 0 | J6: =IFERROR(K6/K$28,0) -> 0 | K6: 0 | L6: =IFERROR(M6/M$28,0) -> 0 | M6: 0 | N6: =IFERROR(O6/O$28,0) -> 0.01202481 | O6: =SUM(C6,E6,G6,I6,K6,M6) -> 4.281406e+08
A7: Chaco | B7: =IFERROR(C7/C$28,0) -> 0.011864623 | C7: 2.1352038e+08 | D7: =IFERROR(E7/E$28,0) -> 0.0081142405 | E7: 81948230 | F7: =IFERROR(G7/G$28,0) -> 0 | G7: 0 | H7: =IFERROR(I7/I$28,0) -> 0 | I7: 0 | J7: =IFERROR(K7/K$28,0) -> 0 | K7: 0 | L7: =IFERROR(M7/M$28,0) -> 0 | M7: 0 | N7: =IFERROR(O7/O$28,0) -> 0.0082985681 | O7: =SUM(C7,E7,G7,I7,K7,M7) -> 2.9546861e+08
A8: Chubut | B8: =IFERROR(C8/C$28,0) -> 0.16467584 | C8: 2963570688 | D8: =IFERROR(E8/E$28,0) -> 0.13641291 | E8: 1.3776762e+09 | F8: =IFERROR(G8/G$28,0) -> 0.019402268 | G8: 145693000 | H8: =IFERROR(I8/I$28,0) -> 0 | I8: 0 | J8: =IFERROR(K8/K$28,0) -> 0 | K8: 0 | L8: =IFERROR(M8/M$28,0) -> 0 | M8: 0 | N8: =IFERROR(O8/O$28,0) -> 0.12602075 | O8: =SUM(C8,E8,G8,I8,K8,M8) -> 4.4869399e+09
A9: Córdoba | B9: =IFERROR(C9/C$28,0) -> 0.035367531 | C9: 6.364879e+08 | D9: =IFERROR(E9/E$28,0) -> 0.0065309808 | E9: 65958399 | F9: =IFERROR(G9/G$28,0) -> 0.0093220593 | G9: 70000000 | H9: =IFERROR(I9/I$28,0) -> 0 | I9: 0 | J9: =IFERROR(K9/K$28,0) -> 0 | K9: 0 | L9: =IFERROR(M9/M$28,0) -> 0 | M9: 0 | N9: =IFERROR(O9/O$28,0) -> 0.021695022 | O9: =SUM(C9,E9,G9,I9,K9,M9) -> 7.724463e+08
A10: Corrientes | B10: =IFERROR(C10/C$28,0) -> 0.010593413 | C10: 190643200 | D10: =IFERROR(E10/E$28,0) -> 0.034777058 | E10: 3.5122429e+08 | F10: =IFERROR(G10/G$28,0) -> 0.0046136139 | G10: 34643952 | H10: =IFERROR(I10/I$28,0) -> 0 | I10: 0 | J10: =IFERROR(K10/K$28,0) -> 0 | K10: 0 | L10: =IFERROR(M10/M$28,0) -> 0 | M10: 0 | N10: =IFERROR(O10/O$28,0) -> 0.016191972 | O10: =SUM(C10,E10,G10,I10,K10,M10) -> 5.7651144e+08
A11: Entre Ríos | B11: =IFERROR(C11/C$28,0) -> 0.020949671 | C11: 3.7701845e+08 | D11: =IFERROR(E11/E$28,0) -> 0.054498795 | E11: 5.5040023e+08 | F11: =IFERROR(G11/G$28,0) -> 0.0032165815 | G11: 24153537 | H11: =IFERROR(I11/I$28,0) -> 0 | I11: 0 | J11: =IFERROR(K11/K$28,0) -> 0 | K11: 0 | L11: =IFERROR(M11/M$28,0) -> 0 | M11: 0 | N11: =IFERROR(O11/O$28,0) -> 0.026725975 | O11: =SUM(C11,E11,G11,I11,K11,M11) -> 9.5157222e+08
A12: Formosa | B12: =IFERROR(C12/C$28,0) -> 0.0084747306 | C12: 152514560 | D12: =IFERROR(E12/E$28,0) -> 0.033957377 | E12: 3.4294608e+08 | F12: =IFERROR(G12/G$28,0) -> 0 | G12: 0 | H12: =IFERROR(I12/I$28,0) -> 0 | I12: 0 | J12: =IFERROR(K12/K$28,0) -> 0 | K12: 0 | L12: =IFERROR(M12/M$28,0) -> 0 | M12: 0 | N12: =IFERROR(O12/O$28,0) -> 0.013915569 | O12: =SUM(C12,E12,G12,I12,K12,M12) -> 4.9546064e+08
A13: Jujuy | B13: =IFERROR(C13/C$28,0) -> 0.010334744 | C13: 1.859881e+08 | D13: =IFERROR(E13/E$28,0) -> 0.023903413 | E13: 2.4140798e+08 | F13: =IFERROR(G13/G$28,0) -> 0 | G13: 0 | H13: =IFERROR(I13/I$28,0) -> 0 | I13: 0 | J13: =IFERROR(K13/K$28,0) -> 0 | K13: 0 | L13: =IFERROR(M13/M$28,0) -> 0 | M13: 0 | N13: =IFERROR(O13/O$28,0) -> 0.012003899 | O13: =SUM(C13,E13,G13,I13,K13,M13) -> 4.2739608e+08
A14: La Pampa | B14: =IFERROR(C14/C$28,0) -> 0.051484378 | C14: 9.2653297e+08 | D14: =IFERROR(E14/E$28,0) -> 0.0032654904 | E14: 32979200 | F14: =IFERROR(G14/G$28,0) -> 0 | G14: 0 | H14: =IFERROR(I14/I$28,0) -> 0 | I14: 0 | J14: =IFERROR(K14/K$28,0) -> 0 | K14: 0 | L14: =IFERROR(M14/M$28,0) -> 0 | M14: 0 | N14: =IFERROR(O14/O$28,0) -> 0.026948978 | O14: =SUM(C14,E14,G14,I14,K14,M14) -> 9.5951217e+08
A15: La Rioja | B15: =IFERROR(C15/C$28,0) -> 0.017716705 | C15: 318836736 | D15: =IFERROR(E15/E$28,0) -> 0.0060460966 | E15: 61061404 | F15: =IFERROR(G15/G$28,0) -> 0 | G15: 0 | H15: =IFERROR(I15/I$28,0) -> 0 | I15: 0 | J15: =IFERROR(K15/K$28,0) -> 0 | K15: 0 | L15: =IFERROR(M15/M$28,0) -> 0 | M15: 0 | N15: =IFERROR(O15/O$28,0) -> 0.010669866 | O15: =SUM(C15,E15,G15,I15,K15,M15) -> 3.7989814e+08
... A27: Tucumán | B27: =IFERROR(C27/C$28,0) -> 0.0059055683 | C27: 106278912 | D27: =IFERROR(E27/E$28,0) -> 0.0032654904 | E27: 32979200 | F27: =IFERROR(G27/G$28,0) -> 0 | G27: 0 | H27: =IFERROR(I27/I$28,0) -> 0 | I27: 0 | J27: =IFERROR(K27/K$28,0) -> 0 | K27: 0 | L27: =IFERROR(M27/M$28,0) -> 0 | M27: 0 | N27: =IFERROR(O27/O$28,0) -> 0.0039112206 | O27: =SUM(C27,E27,G27,I27,K27,M27) -> 1.3925811e+08
A28: Total general | B28: =IFERROR(C28/C$28,0) -> 1 | C28: =SUM(C4:C27) -> 17996390400 | D28: =IFERROR(E28/E$28,0) -> 1 | E28: =SUM(E4:E27) -> 1.009931e+10 | F28: =IFERROR(G28/G$28,0) -> 1 | G28: =SUM(G4:G27) -> 7.5090704e+09 | H28: =IFERROR(I28/I$28,0) -> 0 | I28: =SUM(I4:I27) -> 0 | J28: =IFERROR(K28/K$28,0) -> 0 | K28: =SUM(K4:K27) -> 0 | L28: =IFERROR(M28/M$28,0) -> 0 | M28: =SUM(M4:M27) -> 0 | N28: =IFERROR(O28/O$28,0) -> 1 | O28: =SUM(C28,E28,G28,I28,K28,M28) -> 3.5604771e+10
A30: Chequeo | C30: =C28='2.2.Brecha Efectiva x UdM'!F3 -> TRUE | E30: =E28='2.2.Brecha Efectiva x UdM'!F4 -> TRUE | G30: =G28='2.2.Brecha Efectiva x UdM'!F5 -> TRUE | I30: =I28='2.2.Brecha Efectiva x UdM'!F6 -> TRUE | K30: =K28='2.2.Brecha Efectiva x UdM'!F7 -> TRUE | M30: =M28='2.2.Brecha Efectiva x UdM'!F8 -> TRUE | O30: =O28='2.2.Brecha Efectiva x UdM'!F9 -> TRUE
A32: INSTRUCTIVO
A34: Por favor, completar únicamente las columnas correspondiente a la distribución territorial del monto de la brecha en cada una de las UdMs calculadas por la Jurisdicción. Tener en cuenta que se trata de la distribución de la brecha total de cada una en las UdMs (sumatoria de las brechas efectivas) previamente a la realización de cualquier ajuste (Ejemplo en Rojo)
A35: Los montos deben ser completados en pesos, ingresando la cifra completa (no en millones). El Excel mostrará, automáticamente, el monto en formato millones.
A36: Por favor, mantener las provincias ordenadas alfabéticamente.
A38: DSITRIBUCIÓN PROVINCIAL DE LA BRECHA EFECTIVA DE CADA UDM, AJUSTADA POR EL ÍNDICE DE ACTUALIZACIÓN (EJEMPLO PREDETERMINADO: CRECIMIENTO DE LA POBLACIÓN) (un cuadro para cada UdM)
A39: Supuestos:
A40: Supone ponderaciones constantes, a lo largo de los años, de la distribución entre provincias de montos de la UDM.
A41: También supone la utilización de un único índice de actualización (en el ejemplo predeterminado: la tasa de crecimiento de la población nacional) para realizar el ajuste en cada provincia.
A42: Aclaración:
A43: Si la Jurisdicción decidiera estimar un índice de actualización diferente para cada provincia, podrá reemplazar ("pisar") el cálculo predeterminado de los cuadros de resultado con su propia estimación. Luego deberá explicar los índices de actualización utilizados para permitir que los resultados puedan ser interpretados adecuadamente.
A45: Cuadro 2.3.3.1. Distribución provincial de la UdM 1, por brecha efectiva, en millones de pesos, ajustada en función de la tasa de crecimiento de la Poblacional Nacional.
A47: Provincia | B47: UDM | C47: UDM Provincial | D47: 2024 | E47: 2025 | F47: 2026 | G47: 2027 | H47: 2028 | I47: 2029 | J47: 2030 | K47: 2031 | L47: 2032 | M47: 2033 | N47: 2034 | O47: 2035 | P47: 2036 | Q47: 2037 | R47: 2038 | S47: 2039 | T47: 2040 | U47: 2041 | V47: 2042 | W47: 2043 | X47: 2044 | Y47: 2045 | Z47: 2046 | AA47: 2047 | AB47: 2048 | AC47: 2049 | AD47: 2050 | AE47: 2051 | AF47: 2052 | AG47: 2053 | AH47: TOTAL
A48: =A4 -> Buenos Aires | B48: =$C$3 -> Nombre UdM 1 | C48: =CONCATENATE(A48," ",B48) -> Buenos Aires Nombre UdM 1 | D48: =VLOOKUP($A48,$A$4:$O$28,2,0)*(HLOOKUP(D$47,'2.2.Brecha Efectiva x UdM'!$H$25:$AK$32,2,0)) -> 3.2261706e+08 | E48: =VLOOKUP($A48,$A$4:$O$28,2,0)*(HLOOKUP(E$47,'2.2.Brecha Efectiva x UdM'!$H$25:$AK$32,2,0)) -> 3.2540073e+08 | F48: =VLOOKUP($A48,$A$4:$O$28,2,0)*(HLOOKUP(F$47,'2.2.Brecha Efectiva x UdM'!$H$25:$AK$32,2,0)) -> 2.0206281e+08 | G48: =VLOOKUP($A48,$A$4:$O$28,2,0)*(HLOOKUP(G$47,'2.2.Brecha Efectiva x UdM'!$H$25:$AK$32,2,0)) -> 1.602727e+08 | H48: =VLOOKUP($A48,$A$4:$O$28,2,0)*(HLOOKUP(H$47,'2.2.Brecha Efectiva x UdM'!$H$25:$AK$32,2,0)) -> 84545739 | I48: =VLOOKUP($A48,$A$4:$O$28,2,0)*(HLOOKUP(I$47,'2.2.Brecha Efectiva x UdM'!$H$25:$AK$32,2,0)) -> 85206580 | J48: =VLOOKUP($A48,$A$4:$O$28,2,0)*(HLOOKUP(J$47,'2.2.Brecha Efectiva x UdM'!$H$25:$AK$32,2,0)) -> 85855768 | K48: =VLOOKUP($A48,$A$4:$O$28,2,0)*(HLOOKUP(K$47,'2.2.Brecha Efectiva x UdM'!$H$25:$AK$32,2,0)) -> 79795470 | ... AG48: =VLOOKUP($A48,$A$4:$O$28,2,0)*(HLOOKUP(AG$47,'2.2.Brecha Efectiva x UdM'!$H$25:$AK$32,2,0)) -> 0 | AH48: =SUM(D48:AG48) -> 1.5070716e+09
A49: =A5 -> CABA | B49: =$C$3 -> Nombre UdM 1 | C49: =CONCATENATE(A49," ",B49) -> CABA Nombre UdM 1 | D49: =VLOOKUP($A49,$A$4:$O$28,2,0)*(HLOOKUP(D$47,'2.2.Brecha Efectiva x UdM'!$H$25:$AK$32,2,0)) -> 209783.8 | E49: =VLOOKUP($A49,$A$4:$O$28,2,0)*(HLOOKUP(E$47,'2.2.Brecha Efectiva x UdM'!$H$25:$AK$32,2,0)) -> 211593.9 | F49: =VLOOKUP($A49,$A$4:$O$28,2,0)*(HLOOKUP(F$47,'2.2.Brecha Efectiva x UdM'!$H$25:$AK$32,2,0)) -> 131392.63 | G49: =VLOOKUP($A49,$A$4:$O$28,2,0)*(HLOOKUP(G$47,'2.2.Brecha Efectiva x UdM'!$H$25:$AK$32,2,0)) -> 104218.34 | H49: =VLOOKUP($A49,$A$4:$O$28,2,0)*(HLOOKUP(H$47,'2.2.Brecha Efectiva x UdM'!$H$25:$AK$32,2,0)) -> 54976.405 | I49: =VLOOKUP($A49,$A$4:$O$28,2,0)*(HLOOKUP(I$47,'2.2.Brecha Efectiva x UdM'!$H$25:$AK$32,2,0)) -> 55406.121 | J49: =VLOOKUP($A49,$A$4:$O$28,2,0)*(HLOOKUP(J$47,'2.2.Brecha Efectiva x UdM'!$H$25:$AK$32,2,0)) -> 55828.259 | K49: =VLOOKUP($A49,$A$4:$O$28,2,0)*(HLOOKUP(K$47,'2.2.Brecha Efectiva x UdM'!$H$25:$AK$32,2,0)) -> 51887.512 | ... AG49: =VLOOKUP($A49,$A$4:$O$28,2,0)*(HLOOKUP(AG$47,'2.2.Brecha Efectiva x UdM'!$H$25:$AK$32,2,0)) -> 0 | AH49: =SUM(D49:AG49) -> 979982.87
A50: =A6 -> Catamarca | B50: =$C$3 -> Nombre UdM 1 | C50: =CONCATENATE(A50," ",B50) -> Catamarca Nombre UdM 1 | D50: =VLOOKUP($A50,$A$4:$O$28,2,0)*(HLOOKUP(D$47,'2.2.Brecha Efectiva x UdM'!$H$25:$AK$32,2,0)) -> 81529724 | E50: =VLOOKUP($A50,$A$4:$O$28,2,0)*(HLOOKUP(E$47,'2.2.Brecha Efectiva x UdM'!$H$25:$AK$32,2,0)) -> 82233196 | F50: =VLOOKUP($A50,$A$4:$O$28,2,0)*(HLOOKUP(F$47,'2.2.Brecha Efectiva x UdM'!$H$25:$AK$32,2,0)) -> 51064022 | G50: =VLOOKUP($A50,$A$4:$O$28,2,0)*(HLOOKUP(G$47,'2.2.Brecha Efectiva x UdM'!$H$25:$AK$32,2,0)) -> 40503094 | H50: =VLOOKUP($A50,$A$4:$O$28,2,0)*(HLOOKUP(H$47,'2.2.Brecha Efectiva x UdM'!$H$25:$AK$32,2,0)) -> 21365859 | I50: =VLOOKUP($A50,$A$4:$O$28,2,0)*(HLOOKUP(I$47,'2.2.Brecha Efectiva x UdM'!$H$25:$AK$32,2,0)) -> 21532863 | J50: =VLOOKUP($A50,$A$4:$O$28,2,0)*(HLOOKUP(J$47,'2.2.Brecha Efectiva x UdM'!$H$25:$AK$32,2,0)) -> 21696922 | K50: =VLOOKUP($A50,$A$4:$O$28,2,0)*(HLOOKUP(K$47,'2.2.Brecha Efectiva x UdM'!$H$25:$AK$32,2,0)) -> 20165402 | ... AG50: =VLOOKUP($A50,$A$4:$O$28,2,0)*(HLOOKUP(AG$47,'2.2.Brecha Efectiva x UdM'!$H$25:$AK$32,2,0)) -> 0 | AH50: =SUM(D50:AG50) -> 3.8085751e+08
A51: =A7 -> Chaco | B51: =$C$3 -> Nombre UdM 1 | C51: =CONCATENATE(A51," ",B51) -> Chaco Nombre UdM 1 | D51: =VLOOKUP($A51,$A$4:$O$28,2,0)*(HLOOKUP(D$47,'2.2.Brecha Efectiva x UdM'!$H$25:$AK$32,2,0)) -> 46799388 | E51: =VLOOKUP($A51,$A$4:$O$28,2,0)*(HLOOKUP(E$47,'2.2.Brecha Efectiva x UdM'!$H$25:$AK$32,2,0)) -> 47203192 | F51: =VLOOKUP($A51,$A$4:$O$28,2,0)*(HLOOKUP(F$47,'2.2.Brecha Efectiva x UdM'!$H$25:$AK$32,2,0)) -> 29311579 | G51: =VLOOKUP($A51,$A$4:$O$28,2,0)*(HLOOKUP(G$47,'2.2.Brecha Efectiva x UdM'!$H$25:$AK$32,2,0)) -> 23249435 | H51: =VLOOKUP($A51,$A$4:$O$28,2,0)*(HLOOKUP(H$47,'2.2.Brecha Efectiva x UdM'!$H$25:$AK$32,2,0)) -> 12264351 | I51: =VLOOKUP($A51,$A$4:$O$28,2,0)*(HLOOKUP(I$47,'2.2.Brecha Efectiva x UdM'!$H$25:$AK$32,2,0)) -> 12360214 | J51: =VLOOKUP($A51,$A$4:$O$28,2,0)*(HLOOKUP(J$47,'2.2.Brecha Efectiva x UdM'!$H$25:$AK$32,2,0)) -> 12454386 | K51: =VLOOKUP($A51,$A$4:$O$28,2,0)*(HLOOKUP(K$47,'2.2.Brecha Efectiva x UdM'!$H$25:$AK$32,2,0)) -> 11575269 | ... AG51: =VLOOKUP($A51,$A$4:$O$28,2,0)*(HLOOKUP(AG$47,'2.2.Brecha Efectiva x UdM'!$H$25:$AK$32,2,0)) -> 0 | AH51: =SUM(D51:AG51) -> 2.186184e+08
A52: =A8 -> Chubut | B52: =$C$3 -> Nombre UdM 1 | C52: =CONCATENATE(A52," ",B52) -> Chubut Nombre UdM 1 | D52: =VLOOKUP($A52,$A$4:$O$28,2,0)*(HLOOKUP(D$47,'2.2.Brecha Efectiva x UdM'!$H$25:$AK$32,2,0)) -> 6.4955528e+08 | E52: =VLOOKUP($A52,$A$4:$O$28,2,0)*(HLOOKUP(E$47,'2.2.Brecha Efectiva x UdM'!$H$25:$AK$32,2,0)) -> 6.5515991e+08 | F52: =VLOOKUP($A52,$A$4:$O$28,2,0)*(HLOOKUP(F$47,'2.2.Brecha Efectiva x UdM'!$H$25:$AK$32,2,0)) -> 4.0683206e+08 | G52: =VLOOKUP($A52,$A$4:$O$28,2,0)*(HLOOKUP(G$47,'2.2.Brecha Efectiva x UdM'!$H$25:$AK$32,2,0)) -> 3.2269211e+08 | H52: =VLOOKUP($A52,$A$4:$O$28,2,0)*(HLOOKUP(H$47,'2.2.Brecha Efectiva x UdM'!$H$25:$AK$32,2,0)) -> 1.7022389e+08 | I52: =VLOOKUP($A52,$A$4:$O$28,2,0)*(HLOOKUP(I$47,'2.2.Brecha Efectiva x UdM'!$H$25:$AK$32,2,0)) -> 1.7155442e+08 | J52: =VLOOKUP($A52,$A$4:$O$28,2,0)*(HLOOKUP(J$47,'2.2.Brecha Efectiva x UdM'!$H$25:$AK$32,2,0)) -> 1.728615e+08 | K52: =VLOOKUP($A52,$A$4:$O$28,2,0)*(HLOOKUP(K$47,'2.2.Brecha Efectiva x UdM'!$H$25:$AK$32,2,0)) -> 1.6065973e+08 | ... AG52: =VLOOKUP($A52,$A$4:$O$28,2,0)*(HLOOKUP(AG$47,'2.2.Brecha Efectiva x UdM'!$H$25:$AK$32,2,0)) -> 0 | AH52: =SUM(D52:AG52) -> 3.034329e+09
A53: =A9 -> Córdoba | B53: =$C$3 -> Nombre UdM 1 | C53: =CONCATENATE(A53," ",B53) -> Córdoba Nombre UdM 1 | D53: =VLOOKUP($A53,$A$4:$O$28,2,0)*(HLOOKUP(D$47,'2.2.Brecha Efectiva x UdM'!$H$25:$AK$32,2,0)) -> 1.3950539e+08 | E53: =VLOOKUP($A53,$A$4:$O$28,2,0)*(HLOOKUP(E$47,'2.2.Brecha Efectiva x UdM'!$H$25:$AK$32,2,0)) -> 1.407091e+08 | F53: =VLOOKUP($A53,$A$4:$O$28,2,0)*(HLOOKUP(F$47,'2.2.Brecha Efectiva x UdM'!$H$25:$AK$32,2,0)) -> 87375572 | G53: =VLOOKUP($A53,$A$4:$O$28,2,0)*(HLOOKUP(G$47,'2.2.Brecha Efectiva x UdM'!$H$25:$AK$32,2,0)) -> 69304783 | H53: =VLOOKUP($A53,$A$4:$O$28,2,0)*(HLOOKUP(H$47,'2.2.Brecha Efectiva x UdM'!$H$25:$AK$32,2,0)) -> 36559090 | I53: =VLOOKUP($A53,$A$4:$O$28,2,0)*(HLOOKUP(I$47,'2.2.Brecha Efectiva x UdM'!$H$25:$AK$32,2,0)) -> 36844849 | J53: =VLOOKUP($A53,$A$4:$O$28,2,0)*(HLOOKUP(J$47,'2.2.Brecha Efectiva x UdM'!$H$25:$AK$32,2,0)) -> 37125570 | K53: =VLOOKUP($A53,$A$4:$O$28,2,0)*(HLOOKUP(K$47,'2.2.Brecha Efectiva x UdM'!$H$25:$AK$32,2,0)) -> 34504989 | ... AG53: =VLOOKUP($A53,$A$4:$O$28,2,0)*(HLOOKUP(AG$47,'2.2.Brecha Efectiva x UdM'!$H$25:$AK$32,2,0)) -> 0 | AH53: =SUM(D53:AG53) -> 6.516847e+08
A54: =A10 -> Corrientes | B54: =$C$3 -> Nombre UdM 1 | C54: =CONCATENATE(A54," ",B54) -> Corrientes Nombre UdM 1 | D54: =VLOOKUP($A54,$A$4:$O$28,2,0)*(HLOOKUP(D$47,'2.2.Brecha Efectiva x UdM'!$H$25:$AK$32,2,0)) -> 41785168 | E54: =VLOOKUP($A54,$A$4:$O$28,2,0)*(HLOOKUP(E$47,'2.2.Brecha Efectiva x UdM'!$H$25:$AK$32,2,0)) -> 42145707 | F54: =VLOOKUP($A54,$A$4:$O$28,2,0)*(HLOOKUP(F$47,'2.2.Brecha Efectiva x UdM'!$H$25:$AK$32,2,0)) -> 26171053 | G54: =VLOOKUP($A54,$A$4:$O$28,2,0)*(HLOOKUP(G$47,'2.2.Brecha Efectiva x UdM'!$H$25:$AK$32,2,0)) -> 20758424 | H54: =VLOOKUP($A54,$A$4:$O$28,2,0)*(HLOOKUP(H$47,'2.2.Brecha Efectiva x UdM'!$H$25:$AK$32,2,0)) -> 10950313 | I54: =VLOOKUP($A54,$A$4:$O$28,2,0)*(HLOOKUP(I$47,'2.2.Brecha Efectiva x UdM'!$H$25:$AK$32,2,0)) -> 11035905 | J54: =VLOOKUP($A54,$A$4:$O$28,2,0)*(HLOOKUP(J$47,'2.2.Brecha Efectiva x UdM'!$H$25:$AK$32,2,0)) -> 11119987 | K54: =VLOOKUP($A54,$A$4:$O$28,2,0)*(HLOOKUP(K$47,'2.2.Brecha Efectiva x UdM'!$H$25:$AK$32,2,0)) -> 10335061 | ... AG54: =VLOOKUP($A54,$A$4:$O$28,2,0)*(HLOOKUP(AG$47,'2.2.Brecha Efectiva x UdM'!$H$25:$AK$32,2,0)) -> 0 | AH54: =SUM(D54:AG54) -> 1.95195e+08
A55: =A11 -> Entre Ríos | B55: =$C$3 -> Nombre UdM 1 | C55: =CONCATENATE(A55," ",B55) -> Entre Ríos Nombre UdM 1 | D55: =VLOOKUP($A55,$A$4:$O$28,2,0)*(HLOOKUP(D$47,'2.2.Brecha Efectiva x UdM'!$H$25:$AK$32,2,0)) -> 82634886 | E55: =VLOOKUP($A55,$A$4:$O$28,2,0)*(HLOOKUP(E$47,'2.2.Brecha Efectiva x UdM'!$H$25:$AK$32,2,0)) -> 83347894 | F55: =VLOOKUP($A55,$A$4:$O$28,2,0)*(HLOOKUP(F$47,'2.2.Brecha Efectiva x UdM'!$H$25:$AK$32,2,0)) -> 51756212 | G55: =VLOOKUP($A55,$A$4:$O$28,2,0)*(HLOOKUP(G$47,'2.2.Brecha Efectiva x UdM'!$H$25:$AK$32,2,0)) -> 41052127 | H55: =VLOOKUP($A55,$A$4:$O$28,2,0)*(HLOOKUP(H$47,'2.2.Brecha Efectiva x UdM'!$H$25:$AK$32,2,0)) -> 21655481 | I55: =VLOOKUP($A55,$A$4:$O$28,2,0)*(HLOOKUP(I$47,'2.2.Brecha Efectiva x UdM'!$H$25:$AK$32,2,0)) -> 21824748 | J55: =VLOOKUP($A55,$A$4:$O$28,2,0)*(HLOOKUP(J$47,'2.2.Brecha Efectiva x UdM'!$H$25:$AK$32,2,0)) -> 21991030 | K55: =VLOOKUP($A55,$A$4:$O$28,2,0)*(HLOOKUP(K$47,'2.2.Brecha Efectiva x UdM'!$H$25:$AK$32,2,0)) -> 20438750 | ... AG55: =VLOOKUP($A55,$A$4:$O$28,2,0)*(HLOOKUP(AG$47,'2.2.Brecha Efectiva x UdM'!$H$25:$AK$32,2,0)) -> 0 | AH55: =SUM(D55:AG55) -> 3.8602015e+08
A56: =A12 -> Formosa | B56: =$C$3 -> Nombre UdM 1 | C56: =CONCATENATE(A56," ",B56) -> Formosa Nombre UdM 1 | D56: =VLOOKUP($A56,$A$4:$O$28,2,0)*(HLOOKUP(D$47,'2.2.Brecha Efectiva x UdM'!$H$25:$AK$32,2,0)) -> 33428134 | E56: =VLOOKUP($A56,$A$4:$O$28,2,0)*(HLOOKUP(E$47,'2.2.Brecha Efectiva x UdM'!$H$25:$AK$32,2,0)) -> 33716566 | F56: =VLOOKUP($A56,$A$4:$O$28,2,0)*(HLOOKUP(F$47,'2.2.Brecha Efectiva x UdM'!$H$25:$AK$32,2,0)) -> 20936842 | G56: =VLOOKUP($A56,$A$4:$O$28,2,0)*(HLOOKUP(G$47,'2.2.Brecha Efectiva x UdM'!$H$25:$AK$32,2,0)) -> 16606739 | H56: =VLOOKUP($A56,$A$4:$O$28,2,0)*(HLOOKUP(H$47,'2.2.Brecha Efectiva x UdM'!$H$25:$AK$32,2,0)) -> 8760250.6 | I56: =VLOOKUP($A56,$A$4:$O$28,2,0)*(HLOOKUP(I$47,'2.2.Brecha Efectiva x UdM'!$H$25:$AK$32,2,0)) -> 8828724 | J56: =VLOOKUP($A56,$A$4:$O$28,2,0)*(HLOOKUP(J$47,'2.2.Brecha Efectiva x UdM'!$H$25:$AK$32,2,0)) -> 8895989.9 | K56: =VLOOKUP($A56,$A$4:$O$28,2,0)*(HLOOKUP(K$47,'2.2.Brecha Efectiva x UdM'!$H$25:$AK$32,2,0)) -> 8268049 | ... AG56: =VLOOKUP($A56,$A$4:$O$28,2,0)*(HLOOKUP(AG$47,'2.2.Brecha Efectiva x UdM'!$H$25:$AK$32,2,0)) -> 0 | AH56: =SUM(D56:AG56) -> 1.56156e+08
A57: =A13 -> Jujuy | B57: =$C$3 -> Nombre UdM 1 | C57: =CONCATENATE(A57," ",B57) -> Jujuy Nombre UdM 1 | D57: =VLOOKUP($A57,$A$4:$O$28,2,0)*(HLOOKUP(D$47,'2.2.Brecha Efectiva x UdM'!$H$25:$AK$32,2,0)) -> 40764862 | E57: =VLOOKUP($A57,$A$4:$O$28,2,0)*(HLOOKUP(E$47,'2.2.Brecha Efectiva x UdM'!$H$25:$AK$32,2,0)) -> 41116598 | F57: =VLOOKUP($A57,$A$4:$O$28,2,0)*(HLOOKUP(F$47,'2.2.Brecha Efectiva x UdM'!$H$25:$AK$32,2,0)) -> 25532011 | G57: =VLOOKUP($A57,$A$4:$O$28,2,0)*(HLOOKUP(G$47,'2.2.Brecha Efectiva x UdM'!$H$25:$AK$32,2,0)) -> 20251547 | H57: =VLOOKUP($A57,$A$4:$O$28,2,0)*(HLOOKUP(H$47,'2.2.Brecha Efectiva x UdM'!$H$25:$AK$32,2,0)) -> 10682930 | I57: =VLOOKUP($A57,$A$4:$O$28,2,0)*(HLOOKUP(I$47,'2.2.Brecha Efectiva x UdM'!$H$25:$AK$32,2,0)) -> 10766431 | J57: =VLOOKUP($A57,$A$4:$O$28,2,0)*(HLOOKUP(J$47,'2.2.Brecha Efectiva x UdM'!$H$25:$AK$32,2,0)) -> 10848461 | K57: =VLOOKUP($A57,$A$4:$O$28,2,0)*(HLOOKUP(K$47,'2.2.Brecha Efectiva x UdM'!$H$25:$AK$32,2,0)) -> 10082701 | ... AG57: =VLOOKUP($A57,$A$4:$O$28,2,0)*(HLOOKUP(AG$47,'2.2.Brecha Efectiva x UdM'!$H$25:$AK$32,2,0)) -> 0 | AH57: =SUM(D57:AG57) -> 1.9042875e+08
...

Sheet 2.4.Dimension Fisica e Indicad
A1: Cuadro 2.4.6. Dimensión Física e Indicadores de Cobertura, por UdM, (ajustado por Mantenimiento e Índice de Actualización)
A2: JURISDICCIÓN | B2: SECTOR | C2: Unidad de Medida (UdM) | D2: Brecha x UdM (millones $) META 2051 | E2: Plazo (Años) META 2051 | F2: Brecha x UdM (millones $) META 2033 | G2: (%) de la Brecha cubierto en 2033 | H2: Unidades Físicas | I2: Indicadores de Cobertura
A3: ='2.2.Brecha Efectiva x UdM'!A3 -> Nombre Jurisdicción | B3: ='2.2.Brecha Efectiva x UdM'!B3 -> Nombre Sector | C3: ='2.2.Brecha Efectiva x UdM'!C3 -> Nombre UdM 1 | D3: ='2.2.Brecha Efectiva x UdM'!D65 -> 2.026868e+10 | E3: ='2.2.Brecha Efectiva x UdM'!E65 -> 10 | F3: ='2.2.Brecha Efectiva x UdM'!F65 -> 2.026868e+10 | G3: =IFERROR(F3/D3,0) -> 1 | H3: (Ej. UdM1: Red Federal de Fibra Óptica): Construir e iluminar XX kilómetros de fibra óptica, para llegar a los YY kilómetros iluminados. Actualización de equipamiento para multiplicar por ZZ la capacidad de la red troncal. | I3: Permitirá que XX millones de personas accedan a la red troncal (actualmente tienen acceso YY millones). Esto cubrirá el ZZ% de las necesidades estimadas de conexión a internet.
A4: ='2.2.Brecha Efectiva x UdM'!A4 -> Nombre Jurisdicción | B4: ='2.2.Brecha Efectiva x UdM'!B4 -> Nombre Sector | C4: ='2.2.Brecha Efectiva x UdM'!C4 -> Nombre UdM 2 | D4: ='2.2.Brecha Efectiva x UdM'!D66 -> 1.1219988e+10 | E4: ='2.2.Brecha Efectiva x UdM'!E66 -> 3 | F4: ='2.2.Brecha Efectiva x UdM'!F66 -> 1.1219988e+10 | G4: =IFERROR(F4/D4,0) -> 1 | H4: (Ej. UdM2: Plan Satelital): Reactivación de la fabricación y puesta en órbita de un satélite adicional para la flota geoestacionaria de ARSAT. Actualmente se cuentan con X cantidad de satélites. El nuevo satélite contará con prestaciones adicionales, como X, Y, Z. | I4: Brindará conectividad satelital de calidad en XX mil hogares rurales, con una capacidad de tráfico de datos a los YY Gbps, elevando dicha conectividad al ZZ% de la población rural o de difícil acceso (actualmente cubre el VV%).
A5: ='2.2.Brecha Efectiva x UdM'!A5 -> Nombre Jurisdicción | B5: ='2.2.Brecha Efectiva x UdM'!B5 -> Nombre Sector | C5: ='2.2.Brecha Efectiva x UdM'!C5 -> Nombre UdM 3 | D5: ='2.2.Brecha Efectiva x UdM'!D67 -> 8.3286085e+09 | E5: ='2.2.Brecha Efectiva x UdM'!E67 -> 4 | F5: ='2.2.Brecha Efectiva x UdM'!F67 -> 8.3286085e+09 | G5: =IFERROR(F5/D5,0) -> 1 | H5: (Ej. UdM3: Televisión Digital Abierta): Actualizar XX estaciones de transmisión y renovación de la plataforma de transmisión de Televisión Digital Abierta | I5: Posibilitará cubrir el XX% del territorio (actualmente cubre el YY%). ZZ millones de hogares accederán a un servicio de TV de calidad (VV% del total de hogares). Actualmente acceden MM millones (NN% de los hogares) a un servicio que presenta fallas.
A6: ='2.2.Brecha Efectiva x UdM'!A6 -> Nombre Jurisdicción | B6: ='2.2.Brecha Efectiva x UdM'!B6 -> Nombre Sector | C6: ='2.2.Brecha Efectiva x UdM'!C6 -> 0 | D6: ='2.2.Brecha Efectiva x UdM'!D68 -> 0 | E6: ='2.2.Brecha Efectiva x UdM'!E68 -> 0 | F6: ='2.2.Brecha Efectiva x UdM'!F68 -> 0 | G6: =IFERROR(F6/D6,0) -> 0
A7: ='2.2.Brecha Efectiva x UdM'!A7 -> Nombre Jurisdicción | B7: ='2.2.Brecha Efectiva x UdM'!B7 -> Nombre Sector | C7: ='2.2.Brecha Efectiva x UdM'!C7 -> 0 | D7: ='2.2.Brecha Efectiva x UdM'!D69 -> 0 | E7: ='2.2.Brecha Efectiva x UdM'!E69 -> 0 | F7: ='2.2.Brecha Efectiva x UdM'!F69 -> 0 | G7: =IFERROR(F7/D7,0) -> 0
A8: ='2.2.Brecha Efectiva x UdM'!A8 -> Nombre Jurisdicción | B8: ='2.2.Brecha Efectiva x UdM'!B8 -> Nombre Sector | C8: ='2.2.Brecha Efectiva x UdM'!C8 -> 0 | D8: ='2.2.Brecha Efectiva x UdM'!D70 -> 0 | E8: ='2.2.Brecha Efectiva x UdM'!E70 -> 0 | F8: ='2.2.Brecha Efectiva x UdM'!F70 -> 0 | G8: =IFERROR(F8/D8,0) -> 0
A9: TOTAL | D9: ='2.2.Brecha Efectiva x UdM'!D71 -> 3.9817277e+10 | E9: ='2.2.Brecha Efectiva x UdM'!E71 -> 0 | F9: ='2.2.Brecha Efectiva x UdM'!F71 -> 3.9817277e+10 | G9: =IFERROR(F9/D9,0) -> 1
A11: INSTRUCTIVO
A13: Por favor, completar únicamente las columnas H (Unidades Físicas) e I (Indicadores de Cobertura). (Ejemplo en Rojo)
A14: Las metas físicas establecen, para cada UdM, el uso concreto que se le dará a los fondos requeridos para cerrar la brecha (en términos generales, nos referimos a las “cantidades” utilizadas para el cálculo de las brechas -PxQ). Dependiendo del caso, puede expresarse en cantidad de equipos concretos adquiridos (patrulleros, ambulancias, helicópteros, etc); metros cuadrados construidos (o cantidad de establecimientos); KM de ruta pavimentada, vías reparadas, o de redes primarias o secundarias de agua corriente, MW de potencia instalada; o cantidad de conexiones de servicios realizadas, entre algunos ejemplos posibles. Es importante, si se cuenta con la información, indicar también desde qué base se parte actualmente (ej. cuántos son los MW de potencia instalados actualmente), de manera de poder dimensionar la importancia de la brecha en términos físicos.
A16: Los indicadores de cobertura de cada unidad física, expresan qué porcentaje de cobertura se busca alcanzar con la acción física particular, cuántas personas se van a beneficiar de ella, etc. Cada unidad física debe tener uno o más índices de cobertura, que apunten a que las autoridades puedan dimensionar, en términos cuantitativos, en qué grado o en que medida el cumplimiento de la unidad física estaría respondiendo a la solución de una problemática. Por ejemplo: Si el sector Telecomunicaciones tuviera una UDM “Red Federal de Fibra Óptica”, la meta física podría ser “Construir e iluminar 4.400 kilómetros de fibra óptica, para llegar a los 38.800 kilómetros iluminados” (Nótese que se indica tanto el punto de partida existente, como el objetivo al que se quiere llegar). El indicador de cobertura sería “22 millones de personas tendrán acceso a la red troncal (actualmente tienen acceso 20,7 millones). Esto cubrirá el 50% de las necesidades estimadas de conexión a internet”.
A18: Aclaración: Por favor, tener en cuenta que las Unidades Físicas e Indicadores de Cobertura deben ser estimados en función de los montos del Cuadro 2.2.6, es decir, luego de que se hubieran realizado todos los ajustes relacionados con el paso del tiempo hasta cerrar la brecha.
A20: Cuadro 2.4.8. Dimensión Física e Indicadores de Cobertura, por UdM, para la Reposición del Stock de Capital Existente
A21: JURISDICCIÓN | B21: SECTOR | C21: Unidad de Medida (UdM) | D21: Reposiciones del Stock de Capital Existente x UdM (millones $) META 2051 | E21: Plazo (Años) META 2051 | F21: Reposiciones del Stock de Capital Existente x UdM (millones $) META 2033 | G21: (%) de la Brecha cubierto en 2033 | H21: Inversión Física | I21: Indicadores de Cobertura
A22: ='2.2.Brecha Efectiva x UdM'!A3 -> Nombre Jurisdicción | B22: ='2.2.Brecha Efectiva x UdM'!B3 -> Nombre Sector | C22: ='2.2.Brecha Efectiva x UdM'!C3 -> Nombre UdM 1 | D22: ='2.2.Brecha Efectiva x UdM'!D87 -> 3599278080 | E22: ='2.2.Brecha Efectiva x UdM'!E84 -> 0 | F22: ='2.2.Brecha Efectiva x UdM'!F87 -> 3599278080 | G22: =IFERROR(F22/D22,0) -> 1
A23: ='2.2.Brecha Efectiva x UdM'!A4 -> Nombre Jurisdicción | B23: ='2.2.Brecha Efectiva x UdM'!B4 -> Nombre Sector | C23: ='2.2.Brecha Efectiva x UdM'!C4 -> Nombre UdM 2 | D23: ='2.2.Brecha Efectiva x UdM'!D88 -> 2.019862e+09 | E23: ='2.2.Brecha Efectiva x UdM'!E85 -> 0 | F23: ='2.2.Brecha Efectiva x UdM'!F88 -> 2.019862e+09 | G23: =IFERROR(F23/D23,0) -> 1
A24: ='2.2.Brecha Efectiva x UdM'!A5 -> Nombre Jurisdicción | B24: ='2.2.Brecha Efectiva x UdM'!B5 -> Nombre Sector | C24: ='2.2.Brecha Efectiva x UdM'!C5 -> Nombre UdM 3 | D24: ='2.2.Brecha Efectiva x UdM'!D89 -> 1.5018141e+09 | E24: ='2.2.Brecha Efectiva x UdM'!E86 -> 0 | F24: ='2.2.Brecha Efectiva x UdM'!F89 -> 1.5018141e+09 | G24: =IFERROR(F24/D24,0) -> 1
A25: ='2.2.Brecha Efectiva x UdM'!A6 -> Nombre Jurisdicción | B25: ='2.2.Brecha Efectiva x UdM'!B6 -> Nombre Sector | C25: ='2.2.Brecha Efectiva x UdM'!C6 -> 0 | D25: ='2.2.Brecha Efectiva x UdM'!D90 -> 0 | E25: ='2.2.Brecha Efectiva x UdM'!E87 -> 0 | F25: ='2.2.Brecha Efectiva x UdM'!F90 -> 0 | G25: =IFERROR(F25/D25,0) -> 0
A26: ='2.2.Brecha Efectiva x UdM'!A7 -> Nombre Jurisdicción | B26: ='2.2.Brecha Efectiva x UdM'!B7 -> Nombre Sector | C26: ='2.2.Brecha Efectiva x UdM'!C7 -> 0 | D26: ='2.2.Brecha Efectiva x UdM'!D91 -> 0 | E26: ='2.2.Brecha Efectiva x UdM'!E88 -> 0 | F26: ='2.2.Brecha Efectiva x UdM'!F91 -> 0 | G26: =IFERROR(F26/D26,0) -> 0
A27: ='2.2.Brecha Efectiva x UdM'!A8 -> Nombre Jurisdicción | B27: ='2.2.Brecha Efectiva x UdM'!B8 -> Nombre Sector | C27: ='2.2.Brecha Efectiva x UdM'!C8 -> 0 | D27: ='2.2.Brecha Efectiva x UdM'!D92 -> 0 | E27: ='2.2.Brecha Efectiva x UdM'!E89 -> 0 | F27: ='2.2.Brecha Efectiva x UdM'!F92 -> 0 | G27: =IFERROR(F27/D27,0) -> 0
A28: TOTAL | D28: =SUM(D22:D27) -> 7.1209542e+09 | E28: ='2.2.Brecha Efectiva x UdM'!E90 -> 0 | F28: =SUM(F22:F27) -> 7.1209542e+09 | G28: =IFERROR(F28/D28,0) -> 1
A30: INSTRUCTIVO
A32: Por favor, completar únicamente las columnas H (Inversión Física) e I (Indicadores de Cobertura).
A33: Las inversiones físicas establecen, para cada UdM, el uso concreto que se le dará a los fondos requeridos para reposición, de manera de mantener el stock de capital existente.
A35: Los indicadores de cobertura del stock de capital físico, expresan qué porcentaje de cobertura se busca mantener con la acción física particular.
A37: Aclaración: Por favor, tener en cuenta que las Inversiones Físicas e Indicadores de Cobertura referentes al Stock de Capital Existente, deben ser estimados en función de los montos del Cuadro 2.2.8.
